Workbook

Sheet Huong_dan
A1: Mục | B1: Hướng dẫn
A2: Mục đích | B2: Checklist bản gốc sinh từ đặc tả API; tất cả endpoint chưa triển khai. Ngày đặc tả 29/10/2026.
A3: Bắt đầu | B3: Lưu một bản sao workbook để theo dõi thực tế. File master sẽ được ghi lại khi chạy npm run api:build.
A4: Cập nhật | B4: Trong API_Checklist: chọn owner/ưu tiên/trạng thái; đánh dấu 8 bước Q:X; ghi ngày bắt đầu/hạn/ngày xong/PR/bằng chứng test.
A5: Tiến độ | B5: Công thức đếm Xong / 8. Không áp dụng vẫn chưa tính xong: ghi lý do và chỉ đặt Xong khi reviewer xác nhận tiêu chí đã được xử lý.
A6: Hoàn thành | B6: Chỉ chọn Hoàn thành khi DTO, auth/scope, nghiệp vụ/giao dịch, unit/integration test, tài liệu và review đã có bằng chứng. Dropdown trạng thái là nhập tay; dashboard đếm trạng thái, tiến độ kỹ thuật ở cột Y.
A7: Ưu tiên | B7: P0: nền tảng và tính đúng giao dịch; P1: tính năng cơ sở tiếp theo; P2: mở rộng/chính sách chưa chốt. Đây là thứ tự đề xuất, có thể thay.
A8: Tổng quan | B8: Dashboard dùng COUNTIF/COUNTIFS/AVERAGE tham chiếu API_Checklist. Excel tính lại khi mở; workbook chứa công thức, lọc, cố định hàng/cột, dropdown và liên kết trang.
A9: Các sheet | B9: Luong_Nghiep_vu truy vết đủ 47 luồng; Rang_buoc giữ rule nguồn; DTO_Fields giữ đầu vào; Du_lieu lấy từ SQL thật, gồm ALTER; Quyet_dinh liệt kê phần cần chốt.
A10: Phạm vi | B10: Không có backend/cổng thanh toán đã triển khai. Stored procedure có sẵn vẫn cần API/controller/auth/mapping/lỗi/tests; route import/realtime có phụ thuộc riêng.
A11: Tệp liên quan | B11: api-guide.html ở thư mục gốc; docs/api-catalog.json là dữ liệu chung. Mở trang bằng file trực tiếp không cần server; file Excel được tải từ nút trên trang.
A12: Nguồn | B12: business-guide.js; docs/business-rules.md; app.js; house-rights.js; database/schema.sql. Hash nguồn có trong api-catalog.json.
A13: Đồng bộ | B13: node scripts/build-api-guide.cjs (cần Node 22+ và Python 3); npm run api:check kiểm tra dữ liệu/sự tồn tại và cấu trúc Excel. Không chạy migration lên CSDL.

Sheet Tong_quan
A1: Chỉ số / nhóm | B1: Giá trị | C1: Diễn giải / đã xong
A2: Ngày đặc tả | B2: 2026-10-29 | C2: Bản đề xuất; chưa có backend
A3: Tổng API | B3: 176 | C3: Một hàng = một method + path
A4: Tổng luồng | B4: 47 | C4: Gồm các luồng không phải HTTP
A5: Tổng bảng SQL | B5: 43 | C5: Tạo từ schema hiện tại
A6: Hoàn thành | B6: =COUNTIF(API_Checklist!P2:P177,"Hoàn thành") -> 0 | C6: Trạng thái nhập tay
A7: Đang làm | B7: =COUNTIF(API_Checklist!P2:P177,"Đang làm") -> 0
A8: Bị chặn | B8: =COUNTIF(API_Checklist!P2:P177,"Bị chặn") -> 0
A9: Chưa làm | B9: =COUNTIF(API_Checklist!P2:P177,"Chưa làm") -> 176
A10: Chờ review | B10: =COUNTIF(API_Checklist!P2:P177,"Chờ review") -> 0
A11: Tiến độ kỹ thuật TB | B11: =AVERAGE(API_Checklist!Y2:Y177) -> 0 | C11: Đếm 8 bước / endpoint
A12: Hoàn thành nhưng thiếu bước | B12: =COUNTIFS(API_Checklist!P2:P177,"Hoàn thành",API_Checklist!Y2:Y177,"<1") -> 0 | C12: Cần review lại trước nghiệm thu
A13: Theo nhóm | B13: Số API | C13: Đã hoàn thành
A14: Tài khoản & xác minh | B14: =COUNTIF(API_Checklist!B2:B177,A14) -> 28 | C14: =COUNTIFS(API_Checklist!B2:B177,A14,API_Checklist!P2:P177,"Hoàn thành") -> 0
A15: Nhà, quyền cho thuê & phòng | B15: =COUNTIF(API_Checklist!B2:B177,A15) -> 22 | C15: =COUNTIFS(API_Checklist!B2:B177,A15,API_Checklist!P2:P177,"Hoàn thành") -> 0
A16: Tin đăng & tìm phòng | B16: =COUNTIF(API_Checklist!B2:B177,A16) -> 12 | C16: =COUNTIFS(API_Checklist!B2:B177,A16,API_Checklist!P2:P177,"Hoàn thành") -> 0
A17: Hồ sơ & kết nối ở ghép | B17: =COUNTIF(API_Checklist!B2:B177,A17) -> 14 | C17: =COUNTIFS(API_Checklist!B2:B177,A17,API_Checklist!P2:P177,"Hoàn thành") -> 0
A18: Tin nhắn & thông báo | B18: =COUNTIF(API_Checklist!B2:B177,A18) -> 15 | C18: =COUNTIFS(API_Checklist!B2:B177,A18,API_Checklist!P2:P177,"Hoàn thành") -> 0
A19: Hẹn xem & quyết định thuê | B19: =COUNTIF(API_Checklist!B2:B177,A19) -> 10 | C19: =COUNTIFS(API_Checklist!B2:B177,A19,API_Checklist!P2:P177,"Hoàn thành") -> 0
A20: Hợp đồng & vào ở | B20: =COUNTIF(API_Checklist!B2:B177,A20) -> 13 | C20: =COUNTIFS(API_Checklist!B2:B177,A20,API_Checklist!P2:P177,"Hoàn thành") -> 0
A21: Người ở & đại diện | B21: =COUNTIF(API_Checklist!B2:B177,A21) -> 15 | C21: =COUNTIFS(API_Checklist!B2:B177,A21,API_Checklist!P2:P177,"Hoàn thành") -> 0
A22: Gia hạn, đổi phòng, kết thúc | B22: =COUNTIF(API_Checklist!B2:B177,A22) -> 8 | C22: =COUNTIFS(API_Checklist!B2:B177,A22,API_Checklist!P2:P177,"Hoàn thành") -> 0
A23: Dịch vụ & hóa đơn | B23: =COUNTIF(API_Checklist!B2:B177,A23) -> 16 | C23: =COUNTIFS(API_Checklist!B2:B177,A23,API_Checklist!P2:P177,"Hoàn thành") -> 0
A24: Đánh giá & quản trị | B24: =COUNTIF(API_Checklist!B2:B177,A24) -> 18 | C24: =COUNTIFS(API_Checklist!B2:B177,A24,API_Checklist!P2:P177,"Hoàn thành") -> 0
A25: Dữ liệu & tích hợp | B25: =COUNTIF(API_Checklist!B2:B177,A25) -> 5 | C25: =COUNTIFS(API_Checklist!B2:B177,A25,API_Checklist!P2:P177,"Hoàn thành") -> 0

Sheet API_Checklist
A1: Mã API | B1: Nhóm | C1: Luồng liên quan | D1: Method | E1: Endpoint | F1: Chức năng | G1: Quyền truy cập | H1: Ưu tiên | I1: Phụ thuộc / quyết định | J1: SQL / adapter | K1: Request / ràng buộc | L1: Response data | M1: Logic nghiệp vụ | N1: Lỗi cần kiểm tra | O1: Người phụ trách | P1: Trạng thái | Q1: Thiết kế | R1: DTO / Validate | S1: Auth / Scope | T1: Logic / SQL | U1: Unit test | V1: Integration test | W1: Tài liệu | X1: Review | Y1: Tiến độ | Z1: Ngày bắt đầu | AA1: Hạn hoàn thành | AB1: Ngày xong | AC1: PR / commit | AD1: Tiêu chí nghiệm thu | AE1: Bằng chứng test / ghi chú | AF1: Liên kết trang
A2: API-001 | B2: Tài khoản & xác minh | C2: account-access | D2: POST | E2: /api/v1/auth/register | F2: Đăng ký tài khoản người thuê | G2: PUBLIC | H2: P0 | I2: D09: idempotency store nếu chưa có khóa tự nhiên | J2: SERVICE: cần triển khai giao dịch backend | K2: fullName: string (bắt buộc) — 1–150 ký tự. email: string (tùy chọn) — Email chuẩn hóa, ≤150, duy nhất. phoneNumber: string (tùy chọn) — Chuẩn hóa số điện thoại, ≤20, duy nhất. password: string (bắt buộc) — Chính sách mật khẩu backend; không log/lưu nguyên văn. | L2: User {id,fullName,roles,status}; không trả passwordHash | M2: Ít nhất một email/phone; transaction tạo users + tenants + personal_profiles. Không nhận ADMIN/LANDLORD từ body. | N2: 400 BAD_REQUEST 404 RESOURCE_NOT_FOUND 409 STATE_CONFLICT 409 IDEMPOTENCY_KEY_REUSED 422 VALIDATION_ERROR 409 CONTACT_ALREADY_USED 422 CONTACT_REQUIRED | P2: Chưa làm | Q2: Chưa | R2: Chưa | S2: Chưa | T2: Chưa | U2: Chưa | V2: Chưa | W2: Chưa | X2: Chưa | Y2: =COUNTIF(Q2:X2,"Xong")/8 -> 0 | AD2: Happy path: Đăng ký tài khoản người thuê; kiểm tra User {id,fullName,roles,status}; không trả passwordHash. Đầu vào sai/ID ẩn: không lộ dữ liệu riêng tư. Ràng buộc: Email và số điện thoại có khóa duy nhất; phải có ít nhất một thông tin liên hệ. Vai trò chính thuộc TENANT / LANDLORD / ADMIN. Gửi lặp cùng khóa trả kết quả cũ; cùng khóa khác payload trả 409; hai request tranh cùng tài nguyên không vượt hạn mức. Kiểm tra lỗi DB/provider không để lại cập nhật dở hoặc trả thành công giả. | AF2: Mở đặc tả
A3: API-002 | B3: Tài khoản & xác minh | C3: account-access | D3: POST | E3: /api/v1/auth/login | F3: Đăng nhập và mở phiên | G3: PUBLIC | H3: P0 | I3: D09: idempotency store nếu chưa có khóa tự nhiên | J3: SERVICE: cần triển khai giao dịch backend | K3: identifier: string (bắt buộc) — Email hoặc điện thoại đã chuẩn hóa. password: string (bắt buộc) — So sánh hash an toàn. | L3: Session {accessToken,expiresAt,user}; refresh cookie HttpOnly | M3: Chặn LOCKED/DISABLED; rate limit; tạo auth_sessions, lưu hash refresh token. Access token gắn sessionKey. Không dùng bộ chuyển vai trò demo làm xác thực. | N3: 400 BAD_REQUEST 404 RESOURCE_NOT_FOUND 409 STATE_CONFLICT 409 IDEMPOTENCY_KEY_REUSED 422 VALIDATION_ERROR 409 CONTACT_ALREADY_USED 422 CONTACT_REQUIRED | P3: Chưa làm | Q3: Chưa | R3: Chưa | S3: Chưa | T3: Chưa | U3: Chưa | V3: Chưa | W3: Chưa | X3: Chưa | Y3: =COUNTIF(Q3:X3,"Xong")/8 -> 0 | AD3: Happy path: Đăng nhập và mở phiên; kiểm tra Session {accessToken,expiresAt,user}; refresh cookie HttpOnly. Đầu vào sai/ID ẩn: không lộ dữ liệu riêng tư. Ràng buộc: Email và số điện thoại có khóa duy nhất; phải có ít nhất một thông tin liên hệ. Vai trò chính thuộc TENANT / LANDLORD / ADMIN. Gửi lặp cùng khóa trả kết quả cũ; cùng khóa khác payload trả 409; hai request tranh cùng tài nguyên không vượt hạn mức. Kiểm tra lỗi DB/provider không để lại cập nhật dở hoặc trả thành công giả. | AF3: Mở đặc tả
A4: API-003 | B4: Tài khoản & xác minh | C4: account-access | D4: GET | E4: /api/v1/me | F4: Đọc tài khoản và các vai trò thực | G4: USER: tài khoản ACTIVE; chỉ dữ liệu của mình | H4: P0 | I4: Middleware auth/session/role + object scope | J4: READ: truy vấn có scope quyền | K4: Không có JSON body | L4: User {id,fullName,email,phoneNumber,roles,status,profile} | M4: Roles lấy từ tenants/landlords/admins. role trong users là vai trò hiển thị; mỗi request kiểm tra lại quyền đối tượng. | N4: 400 BAD_REQUEST 401 UNAUTHENTICATED 403 FORBIDDEN 404 RESOURCE_NOT_FOUND | P4: Chưa làm | Q4: Chưa | R4: Chưa | S4: Chưa | T4: Chưa | U4: Chưa | V4: Chưa | W4: Chưa | X4: Chưa | Y4: =COUNTIF(Q4:X4,"Xong")/8 -> 0 | AD4: Happy path: Đọc tài khoản và các vai trò thực; kiểm tra User {id,fullName,email,phoneNumber,roles,status,profile}. Thiếu phiên/phiên revoked/actor LOCKED và actor khác chủ hoặc khác participant phải bị chặn. Ràng buộc: Email và số điện thoại có khóa duy nhất; phải có ít nhất một thông tin liên hệ. Vai trò chính thuộc TENANT / LANDLORD / ADMIN. Phân trang/lọc đúng scope; dữ liệu riêng tư bị loại trên server, không chỉ ẩn UI. Kiểm tra lỗi DB/provider không để lại cập nhật dở hoặc trả thành công giả. | AF4: Mở đặc tả
A5: API-004 | B5: Tài khoản & xác minh | C5: profile | D5: PATCH | E5: /api/v1/me/profile | F5: Cập nhật hồ sơ cá nhân | G5: USER: tài khoản ACTIVE; chỉ dữ liệu của mình | H5: P0 | I5: Middleware auth/session/role + object scope D09: idempotency store nếu chưa có khóa tự nhiên | J5: SERVICE: cần triển khai giao dịch backend | K5: fullName: string (tùy chọn) — 1–150 ký tự sau trim. address: string (tùy chọn) — Tối đa 500 ký tự. gender: string (tùy chọn) — Tối đa 30 ký tự. occupation: string (tùy chọn) — Tối đa 150 ký tự. university: string (tùy chọn) — Tối đa 200 ký tự. bio: string (tùy chọn) — Giới hạn API cần cấu hình; SQL TEXT. avatarFileId: id (tùy chọn) — Tệp AVATAR ACTIVE thuộc người dùng. | L5: PersonalProfile sau cập nhật | M5: Chỉ cập nhật whitelist; không sửa role/status/contact xác thực bằng form profile. Tệp avatar phải thuộc mình. Ghi users.full_name và personal_profiles trong một giao dịch. | N5: 400 BAD_REQUEST 401 UNAUTHENTICATED 403 FORBIDDEN 404 RESOURCE_NOT_FOUND 409 STATE_CONFLICT 409 IDEMPOTENCY_KEY_REUSED 422 VALIDATION_ERROR 422 PROFILE_INVALID | P5: Chưa làm | Q5: Chưa | R5: Chưa | S5: Chưa | T5: Chưa | U5: Chưa | V5: Chưa | W5: Chưa | X5: Chưa | Y5: =COUNTIF(Q5:X5,"Xong")/8 -> 0 | AD5: Happy path: Cập nhật hồ sơ cá nhân; kiểm tra PersonalProfile sau cập nhật. Thiếu phiên/phiên revoked/actor LOCKED và actor khác chủ hoặc khác participant phải bị chặn. Ràng buộc: personal_profiles có một hồ sơ cho mỗi user; thông tin cá nhân không mặc định là dữ liệu công khai. Gửi lặp cùng khóa trả kết quả cũ; cùng khóa khác payload trả 409; hai request tranh cùng tài nguyên không vượt hạn mức. Kiểm tra lỗi DB/provider không để lại cập nhật dở hoặc trả thành công giả. | AF5: Mở đặc tả
A6: API-005 | B6: Tài khoản & xác minh | C6: profile | D6: PATCH | E6: /api/v1/me/notification-settings | F6: Cấu hình kênh thông báo | G6: USER: tài khoản ACTIVE; chỉ dữ liệu của mình | H6: P0 | I6: Middleware auth/session/role + object scope D09: idempotency store nếu chưa có khóa tự nhiên D04 | J6: SERVICE: cần triển khai giao dịch backend | K6: inAppEnabled: boolean (tùy chọn) — Ít nhất một field. emailEnabled: boolean (tùy chọn) — Chỉ bật kênh backend hỗ trợ. pushEnabled: boolean (tùy chọn) — Push delivery cần provider/device registry bổ sung. | L6: Settings {inAppEnabled,emailEnabled,pushEnabled} | M6: Cập nhật flags users. Việc bật flag không đồng nghĩa có dịch vụ email/push hiện tại. | N6: 400 BAD_REQUEST 401 UNAUTHENTICATED 403 FORBIDDEN 404 RESOURCE_NOT_FOUND 409 STATE_CONFLICT 409 IDEMPOTENCY_KEY_REUSED 422 VALIDATION_ERROR 422 PROFILE_INVALID | P6: Chưa làm | Q6: Chưa | R6: Chưa | S6: Chưa | T6: Chưa | U6: Chưa | V6: Chưa | W6: Chưa | X6: Chưa | Y6: =COUNTIF(Q6:X6,"Xong")/8 -> 0 | AD6: Happy path: Cấu hình kênh thông báo; kiểm tra Settings {inAppEnabled,emailEnabled,pushEnabled}. Thiếu phiên/phiên revoked/actor LOCKED và actor khác chủ hoặc khác participant phải bị chặn. Ràng buộc: personal_profiles có một hồ sơ cho mỗi user; thông tin cá nhân không mặc định là dữ liệu công khai. Gửi lặp cùng khóa trả kết quả cũ; cùng khóa khác payload trả 409; hai request tranh cùng tài nguyên không vượt hạn mức. Kiểm tra lỗi DB/provider không để lại cập nhật dở hoặc trả thành công giả. | AF6: Mở đặc tả
A7: API-006 | B7: Tài khoản & xác minh | C7: identity | D7: POST | E7: /api/v1/me/identity-verifications | F7: Nộp xác minh danh tính người thuê | G7: TENANT: chỉ chính người thuê và tài nguyên được phép | H7: P0 | I7: Middleware auth/session/role + object scope D09: idempotency store nếu chưa có khóa tự nhiên D05 | J7: SERVICE: cần triển khai giao dịch backend | K7: identityNumber: string (bắt buộc) — 1–30 ký tự, xử lý như dữ liệu riêng tư. identityFileId: id (bắt buộc) — Tệp IDENTITY PRIVATE ACTIVE thuộc người nộp. | L7: IdentityVerification {id,status:PENDING,createdAt} | M7: Chỉ một PENDING/người; lưu số giấy tờ, tệp và hạn lưu theo chính sách. Không công khai giấy tờ. | N7: 400 BAD_REQUEST 401 UNAUTHENTICATED 403 FORBIDDEN 404 RESOURCE_NOT_FOUND 409 STATE_CONFLICT 409 IDEMPOTENCY_KEY_REUSED 422 VALIDATION_ERROR 409 PENDING_VERIFICATION_EXISTS 422 FILE_INVALID | P7: Chưa làm | Q7: Chưa | R7: Chưa | S7: Chưa | T7: Chưa | U7: Chưa | V7: Chưa | W7: Chưa | X7: Chưa | Y7: =COUNTIF(Q7:X7,"Xong")/8 -> 0 | AD7: Happy path: Nộp xác minh danh tính người thuê; kiểm tra IdentityVerification {id,status:PENDING,createdAt}. Thiếu phiên/phiên revoked/actor LOCKED và actor khác chủ hoặc khác participant phải bị chặn. Ràng buộc: Mỗi người chỉ có một hồ sơ xác minh cùng loại đang PENDING; quyết định duyệt/từ chối lưu người và thời điểm. Gửi lặp cùng khóa trả kết quả cũ; cùng khóa khác payload trả 409; hai request tranh cùng tài nguyên không vượt hạn mức. Kiểm tra lỗi DB/provider không để lại cập nhật dở hoặc trả thành công giả. | AF7: Mở đặc tả
A8: API-007 | B8: Tài khoản & xác minh | C8: identity | D8: GET | E8: /api/v1/me/identity-verifications | F8: Lịch sử xác minh của mình | G8: TENANT: chỉ chính người thuê và tài nguyên được phép | H8: P0 | I8: Middleware auth/session/role + object scope | J8: READ: truy vấn có scope quyền | K8: Không có JSON body | L8: IdentityVerification[]; che số giấy tờ, không trả URL kho | M8: Chỉ tenant_id = actor; giấy tờ mở bằng API file có quyền. | N8: 400 BAD_REQUEST 401 UNAUTHENTICATED 403 FORBIDDEN 404 RESOURCE_NOT_FOUND 422 VALIDATION_ERROR | P8: Chưa làm | Q8: Chưa | R8: Chưa | S8: Chưa | T8: Chưa | U8: Chưa | V8: Chưa | W8: Chưa | X8: Chưa | Y8: =COUNTIF(Q8:X8,"Xong")/8 -> 0 | AD8: Happy path: Lịch sử xác minh của mình; kiểm tra IdentityVerification[]; che số giấy tờ, không trả URL kho. Thiếu phiên/phiên revoked/actor LOCKED và actor khác chủ hoặc khác participant phải bị chặn. Ràng buộc: Mỗi người chỉ có một hồ sơ xác minh cùng loại đang PENDING; quyết định duyệt/từ chối lưu người và thời điểm. Phân trang/lọc đúng scope; dữ liệu riêng tư bị loại trên server, không chỉ ẩn UI. Kiểm tra lỗi DB/provider không để lại cập nhật dở hoặc trả thành công giả. | AF8: Mở đặc tả
A9: API-008 | B9: Tài khoản & xác minh | C9: identity | D9: POST | E9: /api/v1/me/identity-verifications/{verificationId}/withdraw | F9: Rút hồ sơ danh tính đang chờ | G9: TENANT: chỉ chính người thuê và tài nguyên được phép | H9: P0 | I9: Middleware auth/session/role + object scope D09: idempotency store nếu chưa có khóa tự nhiên | J9: SERVICE: cần triển khai giao dịch backend | K9: Không có JSON body | L9: IdentityVerification {id,status:WITHDRAWN} | M9: Khóa hồ sơ thuộc mình; chỉ PENDING → WITHDRAWN; giữ lịch sử. | N9: 400 BAD_REQUEST 401 UNAUTHENTICATED 403 FORBIDDEN 404 RESOURCE_NOT_FOUND 409 STATE_CONFLICT 409 IDEMPOTENCY_KEY_REUSED 422 VALIDATION_ERROR 409 PENDING_VERIFICATION_EXISTS 422 FILE_INVALID | P9: Chưa làm | Q9: Chưa | R9: Chưa | S9: Chưa | T9: Chưa | U9: Chưa | V9: Chưa | W9: Chưa | X9: Chưa | Y9: =COUNTIF(Q9:X9,"Xong")/8 -> 0 | AD9: Happy path: Rút hồ sơ danh tính đang chờ; kiểm tra IdentityVerification {id,status:WITHDRAWN}. Thiếu phiên/phiên revoked/actor LOCKED và actor khác chủ hoặc khác participant phải bị chặn. Ràng buộc: Mỗi người chỉ có một hồ sơ xác minh cùng loại đang PENDING; quyết định duyệt/từ chối lưu người và thời điểm. Gửi lặp cùng khóa trả kết quả cũ; cùng khóa khác payload trả 409; hai request tranh cùng tài nguyên không vượt hạn mức. Kiểm tra lỗi DB/provider không để lại cập nhật dở hoặc trả thành công giả. | AF9: Mở đặc tả
A10: API-009 | B10: Tài khoản & xác minh | C10: identity | D10: POST | E10: /api/v1/me/landlord-verifications | F10: Xin cấp vai trò chủ trọ | G10: USER: tài khoản ACTIVE; chỉ dữ liệu của mình | H10: P0 | I10: Middleware auth/session/role + object scope D09: idempotency store nếu chưa có khóa tự nhiên | J10: SERVICE: cần triển khai giao dịch backend | K10: identityNumber: string (bắt buộc) — 1–30 ký tự, xử lý như dữ liệu riêng tư. identityFileId: id (bắt buộc) — Tệp IDENTITY PRIVATE ACTIVE thuộc người nộp. | L10: LandlordVerification {id,status:PENDING} | M10: applicant_user_id lấy từ phiên. Chỉ một PENDING; tệp IDENTITY PRIVATE thuộc mình. Duyệt tài khoản không tự xác minh nhà. | N10: 400 BAD_REQUEST 401 UNAUTHENTICATED 403 FORBIDDEN 404 RESOURCE_NOT_FOUND 409 STATE_CONFLICT 409 IDEMPOTENCY_KEY_REUSED 422 VALIDATION_ERROR 409 PENDING_VERIFICATION_EXISTS 422 FILE_INVALID | P10: Chưa làm | Q10: Chưa | R10: Chưa | S10: Chưa | T10: Chưa | U10: Chưa | V10: Chưa | W10: Chưa | X10: Chưa | Y10: =COUNTIF(Q10:X10,"Xong")/8 -> 0 | AD10: Happy path: Xin cấp vai trò chủ trọ; kiểm tra LandlordVerification {id,status:PENDING}. Thiếu phiên/phiên revoked/actor LOCKED và actor khác chủ hoặc khác participant phải bị chặn. Ràng buộc: Mỗi người chỉ có một hồ sơ xác minh cùng loại đang PENDING; quyết định duyệt/từ chối lưu người và thời điểm. Gửi lặp cùng khóa trả kết quả cũ; cùng khóa khác payload trả 409; hai request tranh cùng tài nguyên không vượt hạn mức. Kiểm tra lỗi DB/provider không để lại cập nhật dở hoặc trả thành công giả. | AF10: Mở đặc tả
A11: API-010 | B11: Tài khoản & xác minh | C11: identity | D11: GET | E11: /api/v1/me/landlord-verifications | F11: Lịch sử hồ sơ xin làm chủ trọ | G11: USER: tài khoản ACTIVE; chỉ dữ liệu của mình | H11: P0 | I11: Middleware auth/session/role + object scope | J11: READ: truy vấn có scope quyền | K11: Không có JSON body | L11: LandlordVerification[] | M11: Chỉ hồ sơ applicant_user_id của mình. | N11: 400 BAD_REQUEST 401 UNAUTHENTICATED 403 FORBIDDEN 404 RESOURCE_NOT_FOUND 422 VALIDATION_ERROR | P11: Chưa làm | Q11: Chưa | R11: Chưa | S11: Chưa | T11: Chưa | U11: Chưa | V11: Chưa | W11: Chưa | X11: Chưa | Y11: =COUNTIF(Q11:X11,"Xong")/8 -> 0 | AD11: Happy path: Lịch sử hồ sơ xin làm chủ trọ; kiểm tra LandlordVerification[]. Thiếu phiên/phiên revoked/actor LOCKED và actor khác chủ hoặc khác participant phải bị chặn. Ràng buộc: Mỗi người chỉ có một hồ sơ xác minh cùng loại đang PENDING; quyết định duyệt/từ chối lưu người và thời điểm. Phân trang/lọc đúng scope; dữ liệu riêng tư bị loại trên server, không chỉ ẩn UI. Kiểm tra lỗi DB/provider không để lại cập nhật dở hoặc trả thành công giả. | AF11: Mở đặc tả
A12: API-011 | B12: Tài khoản & xác minh | C12: identity | D12: POST | E12: /api/v1/me/landlord-verifications/{verificationId}/withdraw | F12: Rút hồ sơ chủ trọ đang chờ | G12: USER: tài khoản ACTIVE; chỉ dữ liệu của mình | H12: P0 | I12: Middleware auth/session/role + object scope D09: idempotency store nếu chưa có khóa tự nhiên | J12: SERVICE: cần triển khai giao dịch backend | K12: Không có JSON body | L12: LandlordVerification {id,status:WITHDRAWN} | M12: Chỉ applicant và hồ sơ PENDING; không thu hồi vai trò đã có. | N12: 400 BAD_REQUEST 401 UNAUTHENTICATED 403 FORBIDDEN 404 RESOURCE_NOT_FOUND 409 STATE_CONFLICT 409 IDEMPOTENCY_KEY_REUSED 422 VALIDATION_ERROR 409 PENDING_VERIFICATION_EXISTS 422 FILE_INVALID | P12: Chưa làm | Q12: Chưa | R12: Chưa | S12: Chưa | T12: Chưa | U12: Chưa | V12: Chưa | W12: Chưa | X12: Chưa | Y12: =COUNTIF(Q12:X12,"Xong")/8 -> 0 | AD12: Happy path: Rút hồ sơ chủ trọ đang chờ; kiểm tra LandlordVerification {id,status:WITHDRAWN}. Thiếu phiên/phiên revoked/actor LOCKED và actor khác chủ hoặc khác participant phải bị chặn. Ràng buộc: Mỗi người chỉ có một hồ sơ xác minh cùng loại đang PENDING; quyết định duyệt/từ chối lưu người và thời điểm. Gửi lặp cùng khóa trả kết quả cũ; cùng khóa khác payload trả 409; hai request tranh cùng tài nguyên không vượt hạn mức. Kiểm tra lỗi DB/provider không để lại cập nhật dở hoặc trả thành công giả. | AF12: Mở đặc tả
A13: API-012 | B13: Tài khoản & xác minh | C13: identity | D13: GET | E13: /api/v1/admin/identity-verifications | F13: Danh sách hồ sơ identity | G13: ADMIN: tài khoản ACTIVE có dòng admins | H13: P0 | I13: Middleware auth/session/role + object scope | J13: READ: truy vấn có scope quyền | K13: Không có JSON body | L13: Verification[]; status,applicant,submittedAt | M13: Lọc status/ngày; không nhúng bytes giấy tờ vào danh sách. | N13: 400 BAD_REQUEST 401 UNAUTHENTICATED 403 FORBIDDEN 404 RESOURCE_NOT_FOUND 422 VALIDATION_ERROR | P13: Chưa làm | Q13: Chưa | R13: Chưa | S13: Chưa | T13: Chưa | U13: Chưa | V13: Chưa | W13: Chưa | X13: Chưa | Y13: =COUNTIF(Q13:X13,"Xong")/8 -> 0 | AD13: Happy path: Danh sách hồ sơ identity; kiểm tra Verification[]; status,applicant,submittedAt. Thiếu phiên/phiên revoked/actor LOCKED và actor khác chủ hoặc khác participant phải bị chặn. Ràng buộc: Mỗi người chỉ có một hồ sơ xác minh cùng loại đang PENDING; quyết định duyệt/từ chối lưu người và thời điểm. Phân trang/lọc đúng scope; dữ liệu riêng tư bị loại trên server, không chỉ ẩn UI. Kiểm tra lỗi DB/provider không để lại cập nhật dở hoặc trả thành công giả. | AF13: Mở đặc tả
... A46: API-045 | B46: Nhà, quyền cho thuê & phòng | C46: rooms | D46: PUT | E46: /api/v1/rooms/{roomId}/capacity | F46: Đổi sức chứa có khóa phòng | G46: LANDLORD: sở hữu nhà/phòng/hợp đồng | H46: P0 | I46: Middleware auth/session/role + object scope D09: idempotency store nếu chưa có khóa tự nhiên | J46: sp_set_room_capacity | K46: capacity: integer (bắt buộc) — >0 và ≥ ACTIVE + PLANNED mở + hold còn hạn. | L46: Room {id,capacity,currentLoad} | M46: API kiểm tra actor ACTIVE rồi gọi procedure, không chỉ đếm phía client. | N46: 400 BAD_REQUEST 401 UNAUTHENTICATED 403 FORBIDDEN 404 RESOURCE_NOT_FOUND 409 STATE_CONFLICT 409 IDEMPOTENCY_KEY_REUSED 422 VALIDATION_ERROR 409 ROOM_NUMBER_EXISTS 422 ROOM_CAPACITY_EXCEEDED 409 ROOM_STILL_OCCUPIED | P46: Chưa làm | Q46: Chưa | R46: Chưa | S46: Chưa | T46: Chưa | U46: Chưa | V46: Chưa | W46: Chưa | X46: Chưa | Y46: =COUNTIF(Q46:X46,"Xong")/8 -> 0 | AD46: Happy path: Đổi sức chứa có khóa phòng; kiểm tra Room {id,capacity,currentLoad}. Thiếu phiên/phiên revoked/actor LOCKED và actor khác chủ hoặc khác participant phải bị chặn. Ràng buộc: Mã phòng duy nhất trong cùng nhà; sức chứa nguyên dương, giá/cọc không âm, diện tích dương. Gửi lặp cùng khóa trả kết quả cũ; cùng khóa khác payload trả 409; hai request tranh cùng tài nguyên không vượt hạn mức. Lỗi giữa giao dịch phải rollback; xác minh không bọc CALL trong transaction của ứng dụng. | AF46: Mở đặc tả
A47: API-046 | B47: Nhà, quyền cho thuê & phòng | C47: room-detail | D47: GET | E47: /api/v1/rooms/{roomId} | F47: Chi tiết phòng theo quyền người xem | G47: PUBLIC | H47: P0 | J47: READ: truy vấn có scope quyền | K47: Không có JSON body | L47: Room {id,area,rentAmount,depositAmount,capacity,status,activeCount,services}; không có danh tính cư dân | M47: Người ngoài chỉ đọc phòng có tin công khai đủ quyền. Chủ/admin xem theo phạm vi được xác thực. Tách số lượng công khai khỏi danh sách người ở. | N47: 400 BAD_REQUEST 404 RESOURCE_NOT_FOUND | P47: Chưa làm | Q47: Chưa | R47: Chưa | S47: Chưa | T47: Chưa | U47: Chưa | V47: Chưa | W47: Chưa | X47: Chưa | Y47: =COUNTIF(Q47:X47,"Xong")/8 -> 0 | AD47: Happy path: Chi tiết phòng theo quyền người xem; kiểm tra Room {id,area,rentAmount,depositAmount,capacity,status,activeCount,services}; không có danh tính cư dân. Đầu vào sai/ID ẩn: không lộ dữ liệu riêng tư. Ràng buộc: Kiểm tra kiểu dữ liệu và quan hệ FK. Phân trang/lọc đúng scope; dữ liệu riêng tư bị loại trên server, không chỉ ẩn UI. Kiểm tra lỗi DB/provider không để lại cập nhật dở hoặc trả thành công giả. | AF47: Mở đặc tả
A48: API-047 | B48: Nhà, quyền cho thuê & phòng | C48: room-detail | D48: GET | E48: /api/v1/rooms/{roomId}/posts | F48: Bài đăng của một phòng | G48: PUBLIC | H48: P0 | J48: READ: truy vấn có scope quyền | K48: Không có JSON body | L48: Post[]; chủ/admin thêm pendingReviewCount và quota=3 | M48: Public chỉ từ v_public_house_posts; chủ sở hữu/admin có thể xem mọi trạng thái của phòng có quyền. Không trả nháp cho người thuê. | N48: 400 BAD_REQUEST 404 RESOURCE_NOT_FOUND 422 VALIDATION_ERROR | P48: Chưa làm | Q48: Chưa | R48: Chưa | S48: Chưa | T48: Chưa | U48: Chưa | V48: Chưa | W48: Chưa | X48: Chưa | Y48: =COUNTIF(Q48:X48,"Xong")/8 -> 0 | AD48: Happy path: Bài đăng của một phòng; kiểm tra Post[]; chủ/admin thêm pendingReviewCount và quota=3. Đầu vào sai/ID ẩn: không lộ dữ liệu riêng tư. Ràng buộc: Kiểm tra kiểu dữ liệu và quan hệ FK. Phân trang/lọc đúng scope; dữ liệu riêng tư bị loại trên server, không chỉ ẩn UI. Kiểm tra lỗi DB/provider không để lại cập nhật dở hoặc trả thành công giả. | AF48: Mở đặc tả
A49: API-048 | B49: Nhà, quyền cho thuê & phòng | C49: room-detail | D49: GET | E49: /api/v1/rooms/{roomId}/residents | F49: Người đang ở trong phòng | G49: LANDLORD: sở hữu nhà/phòng/hợp đồng hoặc ADMIN | H49: P0 | I49: Middleware auth/session/role + object scope | J49: READ: truy vấn có scope quyền | K49: Không có JSON body | L49: Resident[] {id,fullName,isRepresentative,moveInDate,reconciliationRequired} | M49: Chỉ ACTIVE, kể cả contract đã đóng sai; không trộn PLANNED/LEFT/CANCELLED; trả 403 cho người ngoài. | N49: 400 BAD_REQUEST 401 UNAUTHENTICATED 403 FORBIDDEN 404 RESOURCE_NOT_FOUND 422 VALIDATION_ERROR | P49: Chưa làm | Q49: Chưa | R49: Chưa | S49: Chưa | T49: Chưa | U49: Chưa | V49: Chưa | W49: Chưa | X49: Chưa | Y49: =COUNTIF(Q49:X49,"Xong")/8 -> 0 | AD49: Happy path: Người đang ở trong phòng; kiểm tra Resident[] {id,fullName,isRepresentative,moveInDate,reconciliationRequired}. Thiếu phiên/phiên revoked/actor LOCKED và actor khác chủ hoặc khác participant phải bị chặn. Ràng buộc: Kiểm tra kiểu dữ liệu và quan hệ FK. Phân trang/lọc đúng scope; dữ liệu riêng tư bị loại trên server, không chỉ ẩn UI. Kiểm tra lỗi DB/provider không để lại cập nhật dở hoặc trả thành công giả. | AF49: Mở đặc tả
A50: API-049 | B50: Nhà, quyền cho thuê & phòng | C50: room-detail | D50: GET | E50: /api/v1/rooms/{roomId}/services | F50: Dịch vụ hiệu lực của phòng | G50: PUBLIC | H50: P0 | J50: READ: active_room_services | K50: Không có JSON body | L50: EffectiveService[] {name,unit,method,unitPrice} | M50: Kiểm tra quyền xem phòng; active cả house_services và room_services; COALESCE override, 0 là giá hợp lệ. | N50: 400 BAD_REQUEST 404 RESOURCE_NOT_FOUND 422 VALIDATION_ERROR | P50: Chưa làm | Q50: Chưa | R50: Chưa | S50: Chưa | T50: Chưa | U50: Chưa | V50: Chưa | W50: Chưa | X50: Chưa | Y50: =COUNTIF(Q50:X50,"Xong")/8 -> 0 | AD50: Happy path: Dịch vụ hiệu lực của phòng; kiểm tra EffectiveService[] {name,unit,method,unitPrice}. Đầu vào sai/ID ẩn: không lộ dữ liệu riêng tư. Ràng buộc: Kiểm tra kiểu dữ liệu và quan hệ FK. Phân trang/lọc đúng scope; dữ liệu riêng tư bị loại trên server, không chỉ ẩn UI. Kiểm tra lỗi DB/provider không để lại cập nhật dở hoặc trả thành công giả. | AF50: Mở đặc tả
A51: API-050 | B51: Tin đăng & tìm phòng | C51: submit-post | D51: GET | E51: /api/v1/landlord/posts | F51: Danh sách tin chủ trọ quản lý | G51: LANDLORD: sở hữu nhà/phòng/hợp đồng | H51: P1 | I51: Middleware auth/session/role + object scope | J51: READ: truy vấn có scope quyền | K51: Không có JSON body | L51: Post[] {id,roomId,status,contentVersion,pendingReviewCount} | M51: Lọc đúng các phòng thuộc mình; trả đủ mọi trạng thái. | N51: 400 BAD_REQUEST 401 UNAUTHENTICATED 403 FORBIDDEN 404 RESOURCE_NOT_FOUND 422 VALIDATION_ERROR | P51: Chưa làm | Q51: Chưa | R51: Chưa | S51: Chưa | T51: Chưa | U51: Chưa | V51: Chưa | W51: Chưa | X51: Chưa | Y51: =COUNTIF(Q51:X51,"Xong")/8 -> 0 | AD51: Happy path: Danh sách tin chủ trọ quản lý; kiểm tra Post[] {id,roomId,status,contentVersion,pendingReviewCount}. Thiếu phiên/phiên revoked/actor LOCKED và actor khác chủ hoặc khác participant phải bị chặn. Ràng buộc: Một phòng tối đa 3 PENDING_REVIEW qua slot 1–3, UNIQUE (room_id,pending_review_slot) và CHECK. Tổng bài và số bài APPROVED không giới hạn. Phân trang/lọc đúng scope; dữ liệu riêng tư bị loại trên server, không chỉ ẩn UI. Kiểm tra lỗi DB/provider không để lại cập nhật dở hoặc trả thành công giả. | AF51: Mở đặc tả
A52: API-051 | B52: Tin đăng & tìm phòng | C52: submit-post | D52: POST | E52: /api/v1/posts | F52: Tạo bài mới và gửi duyệt | G52: LANDLORD: sở hữu nhà/phòng/hợp đồng | H52: P0 | I52: Middleware auth/session/role + object scope D09: idempotency store nếu chưa có khóa tự nhiên D07 | J52: sp_submit_post | K52: roomId: id (bắt buộc) — Phòng thuộc chủ trọ. Khi sửa giữ nguyên roomId. title: string (bắt buộc) — 1–200 ký tự sau trim. content: string (bắt buộc) — Không trống; posts.content là TEXT (≤65.535 bytes UTF-8), dù tham số procedure LONGTEXT. API kiểm tra byte length trước ghi. imageFileIds: id[] (bắt buộc) — Ít nhất 1 tệp POST_IMAGE ACTIVE của chủ trọ; thứ tự mảng là thứ tự ảnh. amenities: string[] (tùy chọn) — Chuẩn hóa, loại trùng; mỗi amenity ≤100 ký tự theo SQL; giới hạn số mục API cần cấu hình. | L52: Post {id,status:PENDING_REVIEW,contentVersion,pendingReviewCount} | M52: Gọi sp_submit_post(p_post=NULL) cấp slot 1–3, nhà chưa xác minh vẫn nộp chờ được. sp_submit_post không ghi ảnh/amenities: cần mở rộng thủ tục trước khi coi toàn bộ body là nguyên tử. Không tạo post nửa chừng rồi báo thành công. | N52: 400 BAD_REQUEST 401 UNAUTHENTICATED 403 FORBIDDEN 404 RESOURCE_NOT_FOUND 409 STATE_CONFLICT 409 IDEMPOTENCY_KEY_REUSED 422 VALIDATION_ERROR 409 POST_REVIEW_QUOTA_REACHED 409 POST_VERSION_CHANGED 422 POST_IMAGE_INVALID | P52: Chưa làm | Q52: Chưa | R52: Chưa | S52: Chưa | T52: Chưa | U52: Chưa | V52: Chưa | W52: Chưa | X52: Chưa | Y52: =COUNTIF(Q52:X52,"Xong")/8 -> 0 | AD52: Happy path: Tạo bài mới và gửi duyệt; kiểm tra Post {id,status:PENDING_REVIEW,contentVersion,pendingReviewCount}. Thiếu phiên/phiên revoked/actor LOCKED và actor khác chủ hoặc khác participant phải bị chặn. Ràng buộc: Một phòng tối đa 3 PENDING_REVIEW qua slot 1–3, UNIQUE (room_id,pending_review_slot) và CHECK. Tổng bài và số bài APPROVED không giới hạn. Gửi lặp cùng khóa trả kết quả cũ; cùng khóa khác payload trả 409; hai request tranh cùng tài nguyên không vượt hạn mức. Lỗi giữa giao dịch phải rollback; xác minh không bọc CALL trong transaction của ứng dụng. | AF52: Mở đặc tả
A53: API-052 | B53: Tin đăng & tìm phòng | C53: submit-post | D53: PATCH | E53: /api/v1/posts/{postId} | F53: Sửa đúng bài và gửi duyệt lại | G53: LANDLORD: sở hữu nhà/phòng/hợp đồng | H53: P1 | I53: Middleware auth/session/role + object scope D09: idempotency store nếu chưa có khóa tự nhiên D07 D15: kiểm tra version trong khóa | J53: sp_submit_post | K53: roomId: id (tùy chọn) — Phòng thuộc chủ trọ. Khi sửa giữ nguyên roomId. title: string (tùy chọn) — 1–200 ký tự sau trim. content: string (tùy chọn) — Không trống; posts.content là TEXT (≤65.535 bytes UTF-8), dù tham số procedure LONGTEXT. API kiểm tra byte length trước ghi. imageFileIds: id[] (tùy chọn) — Ít nhất 1 tệp POST_IMAGE ACTIVE của chủ trọ; thứ tự mảng là thứ tự ảnh. amenities: string[] (tùy chọn) — Chuẩn hóa, loại trùng; mỗi amenity ≤100 ký tự theo SQL; giới hạn số mục API cần cấu hình. | L53: Post {id,status:PENDING_REVIEW,contentVersion} | M53: Giữ roomId. If-Match → p_expected_version. Sửa bài PENDING giữ slot, bài khác cần slot trống. Ảnh/amenities cần mở rộng procedure cùng transaction; không tác động bài khác. | N53: 400 BAD_REQUEST 401 UNAUTHENTICATED 403 FORBIDDEN 404 RESOURCE_NOT_FOUND 409 STATE_CONFLICT 409 IDEMPOTENCY_KEY_REUSED 422 VALIDATION_ERROR 409 POST_REVIEW_QUOTA_REACHED 409 POST_VERSION_CHANGED 422 POST_IMAGE_INVALID | P53: Chưa làm | Q53: Chưa | R53: Chưa | S53: Chưa | T53: Chưa | U53: Chưa | V53: Chưa | W53: Chưa | X53: Chưa | Y53: =COUNTIF(Q53:X53,"Xong")/8 -> 0 | AD53: Happy path: Sửa đúng bài và gửi duyệt lại; kiểm tra Post {id,status:PENDING_REVIEW,contentVersion}. Thiếu phiên/phiên revoked/actor LOCKED và actor khác chủ hoặc khác participant phải bị chặn. Ràng buộc: Một phòng tối đa 3 PENDING_REVIEW qua slot 1–3, UNIQUE (room_id,pending_review_slot) và CHECK. Tổng bài và số bài APPROVED không giới hạn. Gửi lặp cùng khóa trả kết quả cũ; cùng khóa khác payload trả 409; hai request tranh cùng tài nguyên không vượt hạn mức. Lỗi giữa giao dịch phải rollback; xác minh không bọc CALL trong transaction của ứng dụng. | AF53: Mở đặc tả
A54: API-053 | B54: Tin đăng & tìm phòng | C54: moderate-post | D54: GET | E54: /api/v1/admin/posts | F54: Hàng đợi kiểm duyệt tin | G54: ADMIN: tài khoản ACTIVE có dòng admins | H54: P1 | I54: Middleware auth/session/role + object scope | J54: READ: truy vấn có scope quyền | K54: Không có JSON body | L54: Post[] kèm trạng thái quyền nhà | M54: Lọc trạng thái; đọc tin và ảnh riêng phục vụ kiểm duyệt, không dùng route public. | N54: 400 BAD_REQUEST 401 UNAUTHENTICATED 403 FORBIDDEN 404 RESOURCE_NOT_FOUND 422 VALIDATION_ERROR | P54: Chưa làm | Q54: Chưa | R54: Chưa | S54: Chưa | T54: Chưa | U54: Chưa | V54: Chưa | W54: Chưa | X54: Chưa | Y54: =COUNTIF(Q54:X54,"Xong")/8 -> 0 | AD54: Happy path: Hàng đợi kiểm duyệt tin; kiểm tra Post[] kèm trạng thái quyền nhà. Thiếu phiên/phiên revoked/actor LOCKED và actor khác chủ hoặc khác participant phải bị chặn. Ràng buộc: moderation_actions lưu đối tượng, người xử lý, lý do và bản chụp trước/sau khi có. Phân trang/lọc đúng scope; dữ liệu riêng tư bị loại trên server, không chỉ ẩn UI. Kiểm tra lỗi DB/provider không để lại cập nhật dở hoặc trả thành công giả. | AF54: Mở đặc tả
A55: API-054 | B55: Tin đăng & tìm phòng | C55: moderate-post | D55: POST | E55: /api/v1/admin/posts/{postId}/decision | F55: Duyệt hoặc từ chối đúng bài | G55: ADMIN: tài khoản ACTIVE có dòng admins | H55: P1 | I55: Middleware auth/session/role + object scope D09: idempotency store nếu chưa có khóa tự nhiên D15: kiểm tra version trong khóa | J55: SERVICE: cần triển khai giao dịch backend | K55: decision: enum (bắt buộc) — APPROVE hoặc REJECT. reason: string (tùy chọn) — Bắt buộc khi REJECT; tối đa 1.000 ký tự. | L55: Post và contentVersion | M55: Khóa room + post, kiểm tra If-Match/content_version, PENDING_REVIEW; APPROVE cần quyền nhà hiệu lực; REJECT cần reason. Giải phóng slot; ghi audit + thông báo. | N55: 400 BAD_REQUEST 401 UNAUTHENTICATED 403 FORBIDDEN 404 RESOURCE_NOT_FOUND 409 STATE_CONFLICT 409 IDEMPOTENCY_KEY_REUSED 422 VALIDATION_ERROR 409 MODERATION_STATE_CHANGED 422 HOUSE_RIGHT_NOT_EFFECTIVE | P55: Chưa làm | Q55: Chưa | R55: Chưa | S55: Chưa | T55: Chưa | U55: Chưa | V55: Chưa | W55: Chưa | X55: Chưa | Y55: =COUNTIF(Q55:X55,"Xong")/8 -> 0 | AD55: Happy path: Duyệt hoặc từ chối đúng bài; kiểm tra Post và contentVersion. Thiếu phiên/phiên revoked/actor LOCKED và actor khác chủ hoặc khác participant phải bị chặn. Ràng buộc: moderation_actions lưu đối tượng, người xử lý, lý do và bản chụp trước/sau khi có. Gửi lặp cùng khóa trả kết quả cũ; cùng khóa khác payload trả 409; hai request tranh cùng tài nguyên không vượt hạn mức. Kiểm tra lỗi DB/provider không để lại cập nhật dở hoặc trả thành công giả. | AF55: Mở đặc tả
A56: API-055 | B56: Tin đăng & tìm phòng | C56: moderate-post | D56: POST | E56: /api/v1/posts/{postId}/hide | F56: Ẩn tin đang công khai | G56: LANDLORD: sở hữu nhà/phòng/hợp đồng hoặc ADMIN | H56: P1 | I56: Middleware auth/session/role + object scope D09: idempotency store nếu chưa có khóa tự nhiên | J56: SERVICE: cần triển khai giao dịch backend | K56: reason: string (bắt buộc) — Không chỉ khoảng trắng; tối đa 1.000 ký tự. | L56: Post {id,status:HIDDEN} | M56: Chỉ APPROVED; kiểm tra chủ phòng/admin, không đổi bài khác. Giữ ID đã lưu/chia sẻ; ghi audit. | N56: 400 BAD_REQUEST 401 UNAUTHENTICATED 403 FORBIDDEN 404 RESOURCE_NOT_FOUND 409 STATE_CONFLICT 409 IDEMPOTENCY_KEY_REUSED 422 VALIDATION_ERROR 409 MODERATION_STATE_CHANGED 422 HOUSE_RIGHT_NOT_EFFECTIVE | P56: Chưa làm | Q56: Chưa | R56: Chưa | S56: Chưa | T56: Chưa | U56: Chưa | V56: Chưa | W56: Chưa | X56: Chưa | Y56: =COUNTIF(Q56:X56,"Xong")/8 -> 0 | AD56: Happy path: Ẩn tin đang công khai; kiểm tra Post {id,status:HIDDEN}. Thiếu phiên/phiên revoked/actor LOCKED và actor khác chủ hoặc khác participant phải bị chặn. Ràng buộc: moderation_actions lưu đối tượng, người xử lý, lý do và bản chụp trước/sau khi có. Gửi lặp cùng khóa trả kết quả cũ; cùng khóa khác payload trả 409; hai request tranh cùng tài nguyên không vượt hạn mức. Kiểm tra lỗi DB/provider không để lại cập nhật dở hoặc trả thành công giả. | AF56: Mở đặc tả
A57: API-056 | B57: Tin đăng & tìm phòng | C57: moderate-post | D57: POST | E57: /api/v1/admin/posts/{postId}/restore | F57: Hiện lại tin đã ẩn | G57: ADMIN: tài khoản ACTIVE có dòng admins | H57: P1 | I57: Middleware auth/session/role + object scope D09: idempotency store nếu chưa có khóa tự nhiên | J57: SERVICE: cần triển khai giao dịch backend | K57: reason: string (bắt buộc) — Không chỉ khoảng trắng; tối đa 1.000 ký tự. | L57: Post {id,status:APPROVED} | M57: Chỉ HIDDEN; kiểm tra quyền nhà, giữ nội dung, ghi người/lý do/thời điểm; nếu chủ sửa bài thì phải đi lại hàng chờ. | N57: 400 BAD_REQUEST 401 UNAUTHENTICATED 403 FORBIDDEN 404 RESOURCE_NOT_FOUND 409 STATE_CONFLICT 409 IDEMPOTENCY_KEY_REUSED 422 VALIDATION_ERROR 409 MODERATION_STATE_CHANGED 422 HOUSE_RIGHT_NOT_EFFECTIVE | P57: Chưa làm | Q57: Chưa | R57: Chưa | S57: Chưa | T57: Chưa | U57: Chưa | V57: Chưa | W57: Chưa | X57: Chưa | Y57: =COUNTIF(Q57:X57,"Xong")/8 -> 0 | AD57: Happy path: Hiện lại tin đã ẩn; kiểm tra Post {id,status:APPROVED}. Thiếu phiên/phiên revoked/actor LOCKED và actor khác chủ hoặc khác participant phải bị chặn. Ràng buộc: moderation_actions lưu đối tượng, người xử lý, lý do và bản chụp trước/sau khi có. Gửi lặp cùng khóa trả kết quả cũ; cùng khóa khác payload trả 409; hai request tranh cùng tài nguyên không vượt hạn mức. Kiểm tra lỗi DB/provider không để lại cập nhật dở hoặc trả thành công giả. | AF57: Mở đặc tả
A58: API-057 | B58: Tin đăng & tìm phòng | C58: discover | D58: GET | E58: /api/v1/posts | F58: Khám phá và lọc tin công khai | G58: PUBLIC | H58: P0 | J58: READ: v_public_house_posts | K58: Không có JSON body | L58: Post[] {id,roomId,title,images,room,landlordSummary} | M58: Dùng v_public_house_posts; khám phá loại OCCUPIED, vẫn gắn nhãn RESERVED/MAINTENANCE. q,provinceCode,minArea,maxRent,amenities,lat,lng,radiusKm; tọa độ phải cùng cặp. Khoảng cách do backend tính, không dùng demo distance. | N58: 400 BAD_REQUEST 404 RESOURCE_NOT_FOUND 422 VALIDATION_ERROR | P58: Chưa làm | Q58: Chưa | R58: Chưa | S58: Chưa | T58: Chưa | U58: Chưa | V58: Chưa | W58: Chưa | X58: Chưa | Y58: =COUNTIF(Q58:X58,"Xong")/8 -> 0 | AD58: Happy path: Khám phá và lọc tin công khai; kiểm tra Post[] {id,roomId,title,images,room,landlordSummary}. Đầu vào sai/ID ẩn: không lộ dữ liệu riêng tư. Ràng buộc: favorite_posts chống trùng cặp người thuê + bài đăng; FK giữ tham chiếu đúng bài. Phân trang/lọc đúng scope; dữ liệu riêng tư bị loại trên server, không chỉ ẩn UI. Kiểm tra lỗi DB/provider không để lại cập nhật dở hoặc trả thành công giả. | AF58: Mở đặc tả
A59: API-058 | B59: Tin đăng & tìm phòng | C59: discover | D59: GET | E59: /api/v1/posts/{postId} | F59: Chi tiết đúng tin công khai | G59: PUBLIC | H59: P1 | J59: READ: v_public_house_posts | K59: Không có JSON body | L59: Post {id,roomId,title,content,images,amenities,room,landlordSummary} | M59: Tin không còn quyền/ẩn/từ chối trả 404; không tự thay bài khác cùng roomId. Giá/tình trạng/sức chứa lấy rooms hiện tại. | N59: 400 BAD_REQUEST 404 RESOURCE_NOT_FOUND | P59: Chưa làm | Q59: Chưa | R59: Chưa | S59: Chưa | T59: Chưa | U59: Chưa | V59: Chưa | W59: Chưa | X59: Chưa | Y59: =COUNTIF(Q59:X59,"Xong")/8 -> 0 | AD59: Happy path: Chi tiết đúng tin công khai; kiểm tra Post {id,roomId,title,content,images,amenities,room,landlordSummary}. Đầu vào sai/ID ẩn: không lộ dữ liệu riêng tư. Ràng buộc: favorite_posts chống trùng cặp người thuê + bài đăng; FK giữ tham chiếu đúng bài. Phân trang/lọc đúng scope; dữ liệu riêng tư bị loại trên server, không chỉ ẩn UI. Kiểm tra lỗi DB/provider không để lại cập nhật dở hoặc trả thành công giả. | AF59: Mở đặc tả
A60: API-059 | B60: Tin đăng & tìm phòng | C60: discover | D60: GET | E60: /api/v1/me/favorites | F60: Danh sách bài đã lưu | G60: TENANT: chỉ chính người thuê và tài nguyên được phép | H60: P1 | I60: Middleware auth/session/role + object scope | J60: READ: truy vấn có scope quyền | K60: Không có JSON body | L60: Favorite[] {postId,savedAt,availability,post|null} | M60: Chỉ favorites actor. Nếu bài mất quyền thì trả placeholder không lộ ảnh/tiêu đề cũ. | N60: 400 BAD_REQUEST 401 UNAUTHENTICATED 403 FORBIDDEN 404 RESOURCE_NOT_FOUND 422 VALIDATION_ERROR | P60: Chưa làm | Q60: Chưa | R60: Chưa | S60: Chưa | T60: Chưa | U60: Chưa | V60: Chưa | W60: Chưa | X60: Chưa | Y60: =COUNTIF(Q60:X60,"Xong")/8 -> 0 | AD60: Happy path: Danh sách bài đã lưu; kiểm tra Favorite[] {postId,savedAt,availability,post|null}. Thiếu phiên/phiên revoked/actor LOCKED và actor khác chủ hoặc khác participant phải bị chặn. Ràng buộc: favorite_posts chống trùng cặp người thuê + bài đăng; FK giữ tham chiếu đúng bài. Phân trang/lọc đúng scope; dữ liệu riêng tư bị loại trên server, không chỉ ẩn UI. Kiểm tra lỗi DB/provider không để lại cập nhật dở hoặc trả thành công giả. | AF60: Mở đặc tả
A61: API-060 | B61: Tin đăng & tìm phòng | C61: discover | D61: PUT | E61: /api/v1/me/favorites/{postId} | F61: Lưu bài theo ID | G61: TENANT: chỉ chính người thuê và tài nguyên được phép | H61: P1 | I61: Middleware auth/session/role + object scope D09: idempotency store nếu chưa có khóa tự nhiên | J61: SERVICE: cần triển khai giao dịch backend | K61: Không có JSON body | L61: {postId,saved:true} | M61: Bài còn công khai khi lưu; uq tenant+post chống trùng; gọi lặp cùng kết quả. | N61: 400 BAD_REQUEST 401 UNAUTHENTICATED 403 FORBIDDEN 404 RESOURCE_NOT_FOUND 409 STATE_CONFLICT 409 IDEMPOTENCY_KEY_REUSED 422 VALIDATION_ERROR 404 POST_UNAVAILABLE | P61: Chưa làm | Q61: Chưa | R61: Chưa | S61: Chưa | T61: Chưa | U61: Chưa | V61: Chưa | W61: Chưa | X61: Chưa | Y61: =COUNTIF(Q61:X61,"Xong")/8 -> 0 | AD61: Happy path: Lưu bài theo ID; kiểm tra {postId,saved:true}. Thiếu phiên/phiên revoked/actor LOCKED và actor khác chủ hoặc khác participant phải bị chặn. Ràng buộc: favorite_posts chống trùng cặp người thuê + bài đăng; FK giữ tham chiếu đúng bài. Gửi lặp cùng khóa trả kết quả cũ; cùng khóa khác payload trả 409; hai request tranh cùng tài nguyên không vượt hạn mức. Kiểm tra lỗi DB/provider không để lại cập nhật dở hoặc trả thành công giả. | AF61: Mở đặc tả
A62: API-061 | B62: Tin đăng & tìm phòng | C62: discover | D62: DELETE | E62: /api/v1/me/favorites/{postId} | F62: Bỏ lưu bài | G62: TENANT: chỉ chính người thuê và tài nguyên được phép | H62: P1 | I62: Middleware auth/session/role + object scope D09: idempotency store nếu chưa có khóa tự nhiên | J62: SERVICE: cần triển khai giao dịch backend | K62: Không có JSON body | L62: {postId,saved:false} | M62: Chỉ favorite actor; bỏ lưu được cả khi bài đã ẩn; gọi lặp vẫn thành công. | N62: 400 BAD_REQUEST 401 UNAUTHENTICATED 403 FORBIDDEN 404 RESOURCE_NOT_FOUND 409 STATE_CONFLICT 409 IDEMPOTENCY_KEY_REUSED 422 VALIDATION_ERROR 404 POST_UNAVAILABLE | P62: Chưa làm | Q62: Chưa | R62: Chưa | S62: Chưa | T62: Chưa | U62: Chưa | V62: Chưa | W62: Chưa | X62: Chưa | Y62: =COUNTIF(Q62:X62,"Xong")/8 -> 0 | AD62: Happy path: Bỏ lưu bài; kiểm tra {postId,saved:false}. Thiếu phiên/phiên revoked/actor LOCKED và actor khác chủ hoặc khác participant phải bị chặn. Ràng buộc: favorite_posts chống trùng cặp người thuê + bài đăng; FK giữ tham chiếu đúng bài. Gửi lặp cùng khóa trả kết quả cũ; cùng khóa khác payload trả 409; hai request tranh cùng tài nguyên không vượt hạn mức. Kiểm tra lỗi DB/provider không để lại cập nhật dở hoặc trả thành công giả. | AF62: Mở đặc tả
A63: API-062 | B63: Hồ sơ & kết nối ở ghép | C63: roommate-profile | D63: GET | E63: /api/v1/me/roommate-profile | F63: Đọc hồ sơ ở ghép của mình | G63: TENANT: chỉ chính người thuê và tài nguyên được phép | H63: P1 | I63: Middleware auth/session/role + object scope | J63: READ: truy vấn có scope quyền | K63: Không có JSON body | L63: RoommateProfile hoặc 404 PROFILE_NOT_CREATED | M63: Trả profileVersion/housingStatus/currentRoomTenantId; phát hiện hồ sơ IN_SYSTEM cũ khi cư trú đã đổi. | N63: 400 BAD_REQUEST 401 UNAUTHENTICATED 403 FORBIDDEN 404 RESOURCE_NOT_FOUND | P63: Chưa làm | Q63: Chưa | R63: Chưa | S63: Chưa | T63: Chưa | U63: Chưa | V63: Chưa | W63: Chưa | X63: Chưa | Y63: =COUNTIF(Q63:X63,"Xong")/8 -> 0 | AD63: Happy path: Đọc hồ sơ ở ghép của mình; kiểm tra RoommateProfile hoặc 404 PROFILE_NOT_CREATED. Thiếu phiên/phiên revoked/actor LOCKED và actor khác chủ hoặc khác participant phải bị chặn. Ràng buộc: Một roommate_profiles cho mỗi tenant; ngân sách không âm và max ≥ min nếu có cả hai. Phân trang/lọc đúng scope; dữ liệu riêng tư bị loại trên server, không chỉ ẩn UI. Kiểm tra lỗi DB/provider không để lại cập nhật dở hoặc trả thành công giả. | AF63: Mở đặc tả
A64: API-063 | B64: Hồ sơ & kết nối ở ghép | C64: roommate-profile | D64: PUT | E64: /api/v1/me/roommate-profile | F64: Tạo hoặc thay thế hồ sơ ở ghép | G64: TENANT: chỉ chính người thuê và tài nguyên được phép | H64: P1 | I64: Middleware auth/session/role + object scope D09: idempotency store nếu chưa có khóa tự nhiên D15: kiểm tra version trong khóa | J64: SERVICE: cần triển khai giao dịch backend | K64: housingStatus: enum (bắt buộc) — NO_ACCOMMODATION / EXTERNAL; IN_SYSTEM do server xác định từ ACTIVE. externalContext: string (tùy chọn) — Chỉ EXTERNAL, tối đa 1.000 ký tự. availableFrom: date (bắt buộc) — Ngày hợp lệ. budgetMin: money (tùy chọn) — ≥0. budgetMax: money (tùy chọn) — ≥ budgetMin. preferredLocation: string (bắt buộc) — 1–500 ký tự. preferredGender: string (tùy chọn) — ≤30 ký tự. requirementsSnapshot: object (tùy chọn) — Nhu cầu tự khai; schema cần chốt. active: boolean (bắt buộc) — Bật cho phép tìm kiếm. | L64: RoommateProfile {id,profileVersion,...} | M64: Một hồ sơ/tenant; tra ACTIVE bằng khóa, tự ghi IN_SYSTEM + đúng member nếu có; không tin currentRoomTenantId client. If-Match cho cập nhật, If-None-Match:* khi tạo. Lưu không gửi lời mời. | N64: 400 BAD_REQUEST 401 UNAUTHENTICATED 403 FORBIDDEN 404 RESOURCE_NOT_FOUND 409 STATE_CONFLICT 409 IDEMPOTENCY_KEY_REUSED 422 VALIDATION_ERROR 409 PROFILE_VERSION_CHANGED 422 HOUSING_CONTEXT_INVALID | P64: Chưa làm | Q64: Chưa | R64: Chưa | S64: Chưa | T64: Chưa | U64: Chưa | V64: Chưa | W64: Chưa | X64: Chưa | Y64: =COUNTIF(Q64:X64,"Xong")/8 -> 0 | AD64: Happy path: Tạo hoặc thay thế hồ sơ ở ghép; kiểm tra RoommateProfile {id,profileVersion,...}. Thiếu phiên/phiên revoked/actor LOCKED và actor khác chủ hoặc khác participant phải bị chặn. Ràng buộc: Một roommate_profiles cho mỗi tenant; ngân sách không âm và max ≥ min nếu có cả hai. Gửi lặp cùng khóa trả kết quả cũ; cùng khóa khác payload trả 409; hai request tranh cùng tài nguyên không vượt hạn mức. Kiểm tra lỗi DB/provider không để lại cập nhật dở hoặc trả thành công giả. | AF64: Mở đặc tả
A65: API-064 | B65: Hồ sơ & kết nối ở ghép | C65: roommate-profile | D65: GET | E65: /api/v1/roommate-profiles/{profileId} | F65: Xem hồ sơ ứng viên theo quyền | G65: TENANT: chỉ chính người thuê và tài nguyên được phép | H65: P1 | I65: Middleware auth/session/role + object scope | J65: READ: truy vấn có scope quyền | K65: Không có JSON body | L65: PublicRoommateProfile; không có CCCD/địa chỉ cư trú cụ thể | M65: Hồ sơ active được tìm; người nhận lời mời vẫn được xem nội dung đủ quyết định theo quyền lời mời. Không trả định danh căn cước. | N65: 400 BAD_REQUEST 401 UNAUTHENTICATED 403 FORBIDDEN 404 RESOURCE_NOT_FOUND | P65: Chưa làm | Q65: Chưa | R65: Chưa | S65: Chưa | T65: Chưa | U65: Chưa | V65: Chưa | W65: Chưa | X65: Chưa | Y65: =COUNTIF(Q65:X65,"Xong")/8 -> 0 | AD65: Happy path: Xem hồ sơ ứng viên theo quyền; kiểm tra PublicRoommateProfile; không có CCCD/địa chỉ cư trú cụ thể. Thiếu phiên/phiên revoked/actor LOCKED và actor khác chủ hoặc khác participant phải bị chặn. Ràng buộc: Một roommate_profiles cho mỗi tenant; ngân sách không âm và max ≥ min nếu có cả hai. Phân trang/lọc đúng scope; dữ liệu riêng tư bị loại trên server, không chỉ ẩn UI. Kiểm tra lỗi DB/provider không để lại cập nhật dở hoặc trả thành công giả. | AF65: Mở đặc tả
A66: API-065 | B66: Hồ sơ & kết nối ở ghép | C66: matching-criteria | D66: GET | E66: /api/v1/lifestyle-criteria | F66: Danh mục tiêu chí đang áp dụng | G66: TENANT: chỉ chính người thuê và tài nguyên được phép | H66: P1 | I66: Middleware auth/session/role + object scope | J66: READ: truy vấn có scope quyền | K66: Không có JSON body | L66: LifestyleCriterion[] {id,code,name,category,valueType,allowedValues} | M66: Chỉ active; cấu trúc JSON theo valueType được validate bởi service. | N66: 400 BAD_REQUEST 401 UNAUTHENTICATED 403 FORBIDDEN 404 RESOURCE_NOT_FOUND 422 VALIDATION_ERROR | P66: Chưa làm | Q66: Chưa | R66: Chưa | S66: Chưa | T66: Chưa | U66: Chưa | V66: Chưa | W66: Chưa | X66: Chưa | Y66: =COUNTIF(Q66:X66,"Xong")/8 -> 0 | AD66: Happy path: Danh mục tiêu chí đang áp dụng; kiểm tra LifestyleCriterion[] {id,code,name,category,valueType,allowedValues}. Thiếu phiên/phiên revoked/actor LOCKED và actor khác chủ hoặc khác participant phải bị chặn. Ràng buộc: lifestyle_criteria.code duy nhất; value_type thuộc BOOLEAN / NUMBER / CATEGORY / TIME / RANGE. Phân trang/lọc đúng scope; dữ liệu riêng tư bị loại trên server, không chỉ ẩn UI. Kiểm tra lỗi DB/provider không để lại cập nhật dở hoặc trả thành công giả. | AF66: Mở đặc tả
A67: API-066 | B67: Hồ sơ & kết nối ở ghép | C67: matching-criteria | D67: GET | E67: /api/v1/me/roommate-profile/lifestyles | F67: Đọc đặc điểm và mong muốn đã lưu | G67: TENANT: chỉ chính người thuê và tài nguyên được phép | H67: P1 | I67: Middleware auth/session/role + object scope | J67: READ: truy vấn có scope quyền | K67: Không có JSON body | L67: ProfileLifestyle[] | M67: Chỉ profile actor; trả selfValue/preferredValue/isMandatory/importance. | N67: 400 BAD_REQUEST 401 UNAUTHENTICATED 403 FORBIDDEN 404 RESOURCE_NOT_FOUND 422 VALIDATION_ERROR | P67: Chưa làm | Q67: Chưa | R67: Chưa | S67: Chưa | T67: Chưa | U67: Chưa | V67: Chưa | W67: Chưa | X67: Chưa | Y67: =COUNTIF(Q67:X67,"Xong")/8 -> 0 | AD67: Happy path: Đọc đặc điểm và mong muốn đã lưu; kiểm tra ProfileLifestyle[]. Thiếu phiên/phiên revoked/actor LOCKED và actor khác chủ hoặc khác participant phải bị chặn. Ràng buộc: lifestyle_criteria.code duy nhất; value_type thuộc BOOLEAN / NUMBER / CATEGORY / TIME / RANGE. Phân trang/lọc đúng scope; dữ liệu riêng tư bị loại trên server, không chỉ ẩn UI. Kiểm tra lỗi DB/provider không để lại cập nhật dở hoặc trả thành công giả. | AF67: Mở đặc tả
A68: API-067 | B68: Hồ sơ & kết nối ở ghép | C68: matching-criteria | D68: PUT | E68: /api/v1/me/roommate-profile/lifestyles | F68: Thay bộ tiêu chí của hồ sơ | G68: TENANT: chỉ chính người thuê và tài nguyên được phép | H68: P1 | I68: Middleware auth/session/role + object scope D09: idempotency store nếu chưa có khóa tự nhiên | J68: SERVICE: cần triển khai giao dịch backend | K68: criteria: object[] (bắt buộc) — Mỗi criterionId duy nhất; có selfValue hoặc preferredValue; mandatory cần preferredValue; importance 0–5. | L68: ProfileLifestyle[] và profileVersion | M68: Khóa profile; kiểm tra criterion active, kiểu JSON BOOLEAN/NUMBER/CATEGORY/TIME/RANGE và allowed_values; thay bộ giá trị atomically, tăng profile_version. | N68: 400 BAD_REQUEST 401 UNAUTHENTICATED 403 FORBIDDEN 404 RESOURCE_NOT_FOUND 409 STATE_CONFLICT 409 IDEMPOTENCY_KEY_REUSED 422 VALIDATION_ERROR 422 INVALID_CRITERION_VALUE 409 CRITERION_IN_USE | P68: Chưa làm | Q68: Chưa | R68: Chưa | S68: Chưa | T68: Chưa | U68: Chưa | V68: Chưa | W68: Chưa | X68: Chưa | Y68: =COUNTIF(Q68:X68,"Xong")/8 -> 0 | AD68: Happy path: Thay bộ tiêu chí của hồ sơ; kiểm tra ProfileLifestyle[] và profileVersion. Thiếu phiên/phiên revoked/actor LOCKED và actor khác chủ hoặc khác participant phải bị chặn. Ràng buộc: lifestyle_criteria.code duy nhất; value_type thuộc BOOLEAN / NUMBER / CATEGORY / TIME / RANGE. Gửi lặp cùng khóa trả kết quả cũ; cùng khóa khác payload trả 409; hai request tranh cùng tài nguyên không vượt hạn mức. Kiểm tra lỗi DB/provider không để lại cập nhật dở hoặc trả thành công giả. | AF68: Mở đặc tả
A69: API-068 | B69: Hồ sơ & kết nối ở ghép | C69: matching-criteria | D69: GET | E69: /api/v1/roommate-matches | F69: Danh sách người phù hợp | G69: TENANT: chỉ chính người thuê và tài nguyên được phép | H69: P1 | I69: Middleware auth/session/role + object scope D02 | J69: READ: truy vấn có scope quyền | K69: Không có JSON body | L69: Match[] {profile,score|null,algorithmVersion,explanations} | M69: Loại bản thân, hồ sơ inactive; lọc khu vực/ngân sách/tiêu chí bắt buộc. Thuật toán điểm/trọng số chưa tồn tại: chốt D02 trước khi trả score. | N69: 400 BAD_REQUEST 401 UNAUTHENTICATED 403 FORBIDDEN 404 RESOURCE_NOT_FOUND 422 VALIDATION_ERROR | P69: Chưa làm | Q69: Chưa | R69: Chưa | S69: Chưa | T69: Chưa | U69: Chưa | V69: Chưa | W69: Chưa | X69: Chưa | Y69: =COUNTIF(Q69:X69,"Xong")/8 -> 0 | AD69: Happy path: Danh sách người phù hợp; kiểm tra Match[] {profile,score|null,algorithmVersion,explanations}. Thiếu phiên/phiên revoked/actor LOCKED và actor khác chủ hoặc khác participant phải bị chặn. Ràng buộc: lifestyle_criteria.code duy nhất; value_type thuộc BOOLEAN / NUMBER / CATEGORY / TIME / RANGE. Phân trang/lọc đúng scope; dữ liệu riêng tư bị loại trên server, không chỉ ẩn UI. Kiểm tra lỗi DB/provider không để lại cập nhật dở hoặc trả thành công giả. | AF69: Mở đặc tả
A70: API-069 | B70: Hồ sơ & kết nối ở ghép | C70: matching-criteria | D70: POST | E70: /api/v1/admin/lifestyle-criteria | F70: Tạo tiêu chí ghép linh động | G70: ADMIN: tài khoản ACTIVE có dòng admins | H70: P1 | I70: Middleware auth/session/role + object scope D09: idempotency store nếu chưa có khóa tự nhiên | J70: SERVICE: cần triển khai giao dịch backend | K70: code: string (bắt buộc) — Duy nhất; ≤80 ký tự. name: string (bắt buộc) — ≤100 ký tự. category: string (bắt buộc) — ≤100 ký tự. valueType: enum (bắt buộc) — BOOLEAN/NUMBER/CATEGORY/TIME/RANGE. allowedValues: object (tùy chọn) — JSON phải tương thích kiểu. active: boolean (bắt buộc) — Bật/ngừng. | L70: LifestyleCriterion | M70: Không thêm cột hồ sơ cho từng tiêu chí; ghi audit vận hành riêng nếu cần vì moderation_actions không có target tiêu chí. | N70: 400 BAD_REQUEST 401 UNAUTHENTICATED 403 FORBIDDEN 404 RESOURCE_NOT_FOUND 409 STATE_CONFLICT 409 IDEMPOTENCY_KEY_REUSED 422 VALIDATION_ERROR 422 INVALID_CRITERION_VALUE 409 CRITERION_IN_USE | P70: Chưa làm | Q70: Chưa | R70: Chưa | S70: Chưa | T70: Chưa | U70: Chưa | V70: Chưa | W70: Chưa | X70: Chưa | Y70: =COUNTIF(Q70:X70,"Xong")/8 -> 0 | AD70: Happy path: Tạo tiêu chí ghép linh động; kiểm tra LifestyleCriterion. Thiếu phiên/phiên revoked/actor LOCKED và actor khác chủ hoặc khác participant phải bị chặn. Ràng buộc: lifestyle_criteria.code duy nhất; value_type thuộc BOOLEAN / NUMBER / CATEGORY / TIME / RANGE. Gửi lặp cùng khóa trả kết quả cũ; cùng khóa khác payload trả 409; hai request tranh cùng tài nguyên không vượt hạn mức. Kiểm tra lỗi DB/provider không để lại cập nhật dở hoặc trả thành công giả. | AF70: Mở đặc tả
A71: API-070 | B71: Hồ sơ & kết nối ở ghép | C71: matching-criteria | D71: PATCH | E71: /api/v1/admin/lifestyle-criteria/{criterionId} | F71: Sửa/ngừng tiêu chí | G71: ADMIN: tài khoản ACTIVE có dòng admins | H71: P1 | I71: Middleware auth/session/role + object scope D09: idempotency store nếu chưa có khóa tự nhiên D02 | J71: SERVICE: cần triển khai giao dịch backend | K71: code: string (tùy chọn) — Duy nhất; ≤80 ký tự. name: string (tùy chọn) — ≤100 ký tự. category: string (tùy chọn) — ≤100 ký tự. valueType: enum (tùy chọn) — BOOLEAN/NUMBER/CATEGORY/TIME/RANGE. allowedValues: object (tùy chọn) — JSON phải tương thích kiểu. active: boolean (tùy chọn) — Bật/ngừng. | L71: LifestyleCriterion | M71: Không đổi code/kiểu khiến giá trị lịch sử mất nghĩa; đổi kiểu đang dùng cần phiên bản/migration được thiết kế. | N71: 400 BAD_REQUEST 401 UNAUTHENTICATED 403 FORBIDDEN 404 RESOURCE_NOT_FOUND 409 STATE_CONFLICT 409 IDEMPOTENCY_KEY_REUSED 422 VALIDATION_ERROR 422 INVALID_CRITERION_VALUE 409 CRITERION_IN_USE | P71: Chưa làm | Q71: Chưa | R71: Chưa | S71: Chưa | T71: Chưa | U71: Chưa | V71: Chưa | W71: Chưa | X71: Chưa | Y71: =COUNTIF(Q71:X71,"Xong")/8 -> 0 | AD71: Happy path: Sửa/ngừng tiêu chí; kiểm tra LifestyleCriterion. Thiếu phiên/phiên revoked/actor LOCKED và actor khác chủ hoặc khác participant phải bị chặn. Ràng buộc: lifestyle_criteria.code duy nhất; value_type thuộc BOOLEAN / NUMBER / CATEGORY / TIME / RANGE. Gửi lặp cùng khóa trả kết quả cũ; cùng khóa khác payload trả 409; hai request tranh cùng tài nguyên không vượt hạn mức. Kiểm tra lỗi DB/provider không để lại cập nhật dở hoặc trả thành công giả. | AF71: Mở đặc tả
... A153: API-152 | B153: Dịch vụ & hóa đơn | C153: pay-invoice | D153: POST | E153: /api/v1/invoices/{invoiceId}/replacements | F153: Lập bản nháp thay hóa đơn đã hủy | G153: LANDLORD: sở hữu nhà/phòng/hợp đồng | H153: P1 | I153: Middleware auth/session/role + object scope D09: idempotency store nếu chưa có khóa tự nhiên | J153: SERVICE: cần triển khai giao dịch backend | K153: dueDate: date (bắt buộc) — Không trước ngày phát hành theo chính sách đề xuất. items: InvoiceInputItem[] (bắt buộc) — Có tiền thuê và các dòng dịch vụ/khoản khác; tổng không âm. | L153: Invoice {id,status:DRAFT,replacesInvoiceId} | M153: Hóa đơn nguồn CANCELLED, cùng contract/period; unique active kỳ; links FK, giữ dữ liệu cũ. Đây là service mới chưa có UI đầy đủ. | N153: 400 BAD_REQUEST 401 UNAUTHENTICATED 403 FORBIDDEN 404 RESOURCE_NOT_FOUND 409 STATE_CONFLICT 409 IDEMPOTENCY_KEY_REUSED 422 VALIDATION_ERROR 409 INVOICE_STATE_CHANGED 409 INVOICE_PERIOD_EXISTS 422 INVOICE_TOTAL_INVALID | P153: Chưa làm | Q153: Chưa | R153: Chưa | S153: Chưa | T153: Chưa | U153: Chưa | V153: Chưa | W153: Chưa | X153: Chưa | Y153: =COUNTIF(Q153:X153,"Xong")/8 -> 0 | AD153: Happy path: Lập bản nháp thay hóa đơn đã hủy; kiểm tra Invoice {id,status:DRAFT,replacesInvoiceId}. Thiếu phiên/phiên revoked/actor LOCKED và actor khác chủ hoặc khác participant phải bị chặn. Ràng buộc: PAID cần paid_by_id và paid_at; CANCELLED cần người/thời điểm/lý do. Hóa đơn thay thế phải cùng hợp đồng/kỳ theo FK. Gửi lặp cùng khóa trả kết quả cũ; cùng khóa khác payload trả 409; hai request tranh cùng tài nguyên không vượt hạn mức. Kiểm tra lỗi DB/provider không để lại cập nhật dở hoặc trả thành công giả. | AF153: Mở đặc tả
...

Sheet Luong_Nghiep_vu
A1: ID luồng | B1: Nhóm | C1: Tên luồng | D1: Vai trò | E1: Điểm vào wireframe | F1: API liên quan | G1: Job / vận hành | H1: Trạng thái | I1: Giới hạn | J1: Bảng dữ liệu
