Workbook

Sheet Huong_dan
A1: Mục | B1: Cách sử dụng
A2: Mục tiêu | B2: Phân công 3 người A/B/C theo module và mốc phụ thuộc, bao phủ 176 API. FE và AI để trống. Đây là kế hoạch, chưa có task backend nào được thực hiện.
A3: Tạo bản làm việc | B3: Save As một bản sao trước khi cập nhật. npm run plan:build sẽ thay bản master sinh từ mã nguồn; không ghi tiến độ thực vào master rồi chạy build.
A4: Cách cập nhật | B4: BE_Tasks là nguồn trạng thái chính trong workbook: P chọn trạng thái, Q:W đánh dấu 7 bước, AA:AC nhập ngày, AD:AF lưu PR/bằng chứng/lý do. Tăng chiều cao hàng khi cần đọc đủ nội dung dài.
A5: Hoàn thành | B5: Chọn Hoàn thành sau khi 7 bước Xong, các task phụ thuộc đã Hoàn thành và có bằng chứng tại AE. Cột Z cảnh báo khai báo chưa đủ. Công thức kiểm tra không thay thế review/test thật.
A6: Mốc và SP | B6: 8 mốc là thứ tự tích hợp, không phải các tuần cố định. SP là độ lớn tương đối, không phải ngày công; xem lại sau G1. Chưa gán deadline vì chưa có năng lực/lịch làm việc.
A7: Làm song song | B7: Sau G0 có thể code với fixture/mock cùng contract v1. Chờ tích hợp dùng khi module đã viết nhưng provider thật chưa sẵn sàng. Chỉ nghiệm thu đầy đủ khi phụ thuộc và test liên module đạt.
A8: Tên người thực tế | B8: Điền tên thành viên tương ứng A/B/C tại Tong_quan, cột Tên thực tế; giữ ký hiệu owner để liên kết task/API ổn định. Không đổi owner của một task lẻ rồi cùng sửa một module.
A9: API coverage | B9: API_176 tra trạng thái tự động từ BE_Tasks bằng INDEX/MATCH; mỗi endpoint có đúng một task/owner. Không nhập trạng thái độc lập tại API_176.
A10: Tiến độ tổng | B10: Tong_quan dùng COUNTIF và SUMPRODUCT(SP × tiến độ)/SUM(SP). Tỷ lệ task hoàn thành theo trạng thái là chỉ số khác; review cả cột cảnh báo. Excel tính lại công thức khi mở.
A11: File dùng chung | B11: A là người tích hợp bootstrap/dependency/CI/output SQL. B/C chỉ sửa source SQL đã phân, mỗi người có fixtures/tests riêng. Tất cả đường dẫn backend/** là đề xuất, không phải backend đã có.
A12: Đồng bộ trang | B12: Tiến độ trên trang chỉ lưu trong trình duyệt này; Excel không tự đồng bộ với trang hoặc máy khác. Team nên dùng một bản workbook chung hoặc công cụ task làm nguồn thật.
... A14: Nguồn | B14: docs/api-catalog.json + scripts/work-plan-blueprint.cjs → docs/work-plan.json, work-plan-data.js và file Excel này. Kiểm tra: npm run plan:check; npm run test:work-plan.

Sheet Tong_quan
A1: Chỉ số | B1: Giá trị | C1: Diễn giải / số task | D1: Tên thực tế / đã xong
A2: Ngày kế hoạch | B2: 2026-10-29
A3: Tổng task | B3: 52
A4: Tổng API | B4: 176
A5: Mốc tích hợp | B5: 8
A6: SP dự kiến | B6: 263 | C6: Độ lớn tương đối, không phải ngày công
A7: Hoàn thành | B7: =COUNTIF(BE_Tasks!$P$2:$P$53,"Hoàn thành") -> 0
A8: Đang làm | B8: =COUNTIF(BE_Tasks!$P$2:$P$53,"Đang làm") -> 0
A9: Chờ tích hợp | B9: =COUNTIF(BE_Tasks!$P$2:$P$53,"Chờ tích hợp") -> 0
A10: Chờ review | B10: =COUNTIF(BE_Tasks!$P$2:$P$53,"Chờ review") -> 0
A11: Bị chặn | B11: =COUNTIF(BE_Tasks!$P$2:$P$53,"Bị chặn") -> 0
A12: Chưa làm | B12: =COUNTIF(BE_Tasks!$P$2:$P$53,"Chưa làm") -> 52
A13: Tiến độ theo SP | B13: =SUMPRODUCT(BE_Tasks!G2:G53,BE_Tasks!X2:X53)/SUM(BE_Tasks!G2:G53) -> 0 | C13: 7 bước, có trọng số độ lớn
A14: Hoàn thành nhưng thiếu bằng chứng | B14: =COUNTIF(BE_Tasks!Z2:Z53,"Thiếu*") -> 0 | C14: Cần review lại trước nghiệm thu
A15: Người / vai trò | B15: SP | C15: Số task | D15: Tên thực tế
A16: A — Nền tảng, tài khoản, tương tác & hóa đơn | B16: 86 | C16: 17
A17: B — Nhà/phòng, tin đăng, lịch xem & ở ghép | B17: 91 | C17: 19
A18: C — Hợp đồng, cư trú & thay đổi thuê | B18: 86 | C18: 16
A19: Tiến độ từng người | B19: SP đã xử lý | C19: Tỷ lệ theo SP | D19: Task hoàn thành
A20: A | B20: =SUMPRODUCT((BE_Tasks!$D$2:$D$53="A")*BE_Tasks!$G$2:$G$53*BE_Tasks!$X$2:$X$53) -> 0 | C20: =SUMPRODUCT((BE_Tasks!$D$2:$D$53="A")*BE_Tasks!$G$2:$G$53*BE_Tasks!$X$2:$X$53)/SUMIF(BE_Tasks!$D$2:$D$53,"A",BE_Tasks!$G$2:$G$53) -> 0 | D20: =COUNTIFS(BE_Tasks!$D$2:$D$53,"A",BE_Tasks!$P$2:$P$53,"Hoàn thành") -> 0
A21: B | B21: =SUMPRODUCT((BE_Tasks!$D$2:$D$53="B")*BE_Tasks!$G$2:$G$53*BE_Tasks!$X$2:$X$53) -> 0 | C21: =SUMPRODUCT((BE_Tasks!$D$2:$D$53="B")*BE_Tasks!$G$2:$G$53*BE_Tasks!$X$2:$X$53)/SUMIF(BE_Tasks!$D$2:$D$53,"B",BE_Tasks!$G$2:$G$53) -> 0 | D21: =COUNTIFS(BE_Tasks!$D$2:$D$53,"B",BE_Tasks!$P$2:$P$53,"Hoàn thành") -> 0
A22: C | B22: =SUMPRODUCT((BE_Tasks!$D$2:$D$53="C")*BE_Tasks!$G$2:$G$53*BE_Tasks!$X$2:$X$53) -> 0 | C22: =SUMPRODUCT((BE_Tasks!$D$2:$D$53="C")*BE_Tasks!$G$2:$G$53*BE_Tasks!$X$2:$X$53)/SUMIF(BE_Tasks!$D$2:$D$53,"C",BE_Tasks!$G$2:$G$53) -> 0 | D22: =COUNTIFS(BE_Tasks!$D$2:$D$53,"C",BE_Tasks!$P$2:$P$53,"Hoàn thành") -> 0

Sheet BE_Tasks
A1: Task ID | B1: Mốc | C1: Thứ tự trong lane | D1: Owner | E1: Reviewer | F1: Công việc | G1: SP tương đối | H1: Số API | I1: API ID | J1: Phạm vi file được sửa | K1: Phụ thuộc trước tích hợp | L1: Cần phối hợp nghiệm thu | M1: Quyết định liên quan | N1: Đầu ra bàn giao | O1: Tiêu chí nghiệm thu | P1: Trạng thái | Q1: Thiết kế / contract | R1: Code / SQL | S1: Validate / phân quyền | T1: Test module / DB | U1: Test tích hợp | V1: Tài liệu / bàn giao | W1: Review / merge | X1: Tiến độ 7 bước | Y1: Điều kiện nghiệm thu | Z1: Cảnh báo hoàn thành | AA1: Bắt đầu | AB1: Hạn | AC1: Ngày xong | AD1: PR / commit | AE1: Bằng chứng test / quyết định | AF1: Ghi chú / lý do bị chặn | AG1: Link task
A2: BE-A01 | B2: P0 | C2: 1 | D2: A | E2: B | F2: Khởi tạo backend, nhánh và CI theo module | G2: 3 | H2: 0 | J2: backend/src/core/** backend/contracts/core.* backend/tests/fixtures/A/** backend/tests/contracts/A/** backend/tests/e2e/platform-*/** backend/bootstrap.* backend/package* backend/lockfile .github/workflows/backend-* database/schema.sql database/migrations/* scripts/build-database.cjs backend/tests/e2e/release/** | M2: D15 | N2: Tạo backend/src/modules/<domain>, tests/fixtures theo module và manifest tự đăng ký. Mỗi PR có branch be/<owner>/<task-id>-<slug>; main được bảo vệ bằng review và CI. CI dựng SQL từ nguồn vào thư mục tạm cho feature PR; A giữ output SQL tích hợp khớp nguồn khi merge. | O2: Lệnh chạy và test được ghi trong README backend; không dùng DB thật để test. B/C thêm module qua manifest riêng mà không sửa bootstrap, lockfile hay root routes. | P2: Chưa làm | Q2: Chưa | R2: Chưa | S2: Chưa | T2: Chưa | U2: Chưa | V2: Chưa | W2: Chưa | X2: =COUNTIF(Q2:W2,"Xong")/7 -> 0 | Y2: =IF(TRUE,"Đủ điều kiện","Chờ phụ thuộc") -> Đủ điều kiện | Z2: =IF(AND(P2="Hoàn thành",OR(X2<1,Y2<>"Đủ điều kiện",AND(AE2="",AD2=""))),"Thiếu bước / phụ thuộc / bằng chứng","") | AG2: Mở task
A3: BE-A02 | B3: P0 | C3: 2 | D3: A | E3: B | F3: Chốt contract v1 và cổng dùng chung | G3: 5 | H3: 0 | J3: backend/src/core/** backend/contracts/core.* backend/tests/fixtures/A/** backend/tests/contracts/A/** backend/tests/e2e/platform-*/** backend/bootstrap.* backend/package* backend/lockfile .github/workflows/backend-* | K3: BE-A01 | M3: D01, D09, D14, D15 | N3: Công bố backend/contracts/core.* với fixture request/response/error và mock adapter. Tách UnitOfWork của service với ProcedureRunner tự START/COMMIT; actor luôn lấy từ phiên. Định nghĩa eventId/recipient/eventKey, idempotency scope và whitelist audit target; B/C có contract test dùng ngay. | O3: B01/C01 cùng duyệt contract v1 trước khi merge code tích hợp. Contract test chạy với mock và adapter thật mà không sửa code consumer. | P3: Chưa làm | Q3: Chưa | R3: Chưa | S3: Chưa | T3: Chưa | U3: Chưa | V3: Chưa | W3: Chưa | X3: =COUNTIF(Q3:W3,"Xong")/7 -> 0 | Y3: =IF(AND(AND(INDEX(BE_Tasks!$P$2:$P$53,MATCH("BE-A01",BE_Tasks!$A$2:$A$53,0))="Hoàn thành",INDEX(BE_Tasks!$Z$2:$Z$53,MATCH("BE-A01",BE_Tasks!$A$2:$A$53,0))="")),"Đủ điều kiện","Chờ phụ thuộc") -> Chờ phụ thuộc | Z3: =IF(AND(P3="Hoàn thành",OR(X3<1,Y3<>"Đủ điều kiện",AND(AE3="",AD3=""))),"Thiếu bước / phụ thuộc / bằng chứng","") | AG3: Mở task
A4: BE-A03 | B4: P1 | C4: 3 | D4: A | E4: B | F4: Xác thực, phiên, profile và scope quyền | G4: 8 | H4: 9 | I4: API-001, API-002, API-003, API-004, API-005, API-018, API-019, API-020, API-021 | J4: backend/src/modules/identity/** backend/tests/identity/** backend/contracts/identity.* | K4: BE-A02 | M4: D01 | N4: Register users+tenants+profile nguyên tử; không nhận ADMIN/LANDLORD tùy ý từ client. Refresh xoay token, session revoked/LOCKED bị chặn; profile và flags theo whitelist. Cung cấp factory actor/phiên test cho B/C, tách policy role với quyền từng đối tượng. | O4: Thiếu token 401; sai scope/LOCKED không truy cập được tài nguyên module khác. Mọi contact/ID/money/date validate theo đặc tả, không log secret. | P4: Chưa làm | Q4: Chưa | R4: Chưa | S4: Chưa | T4: Chưa | U4: Chưa | V4: Chưa | W4: Chưa | X4: =COUNTIF(Q4:W4,"Xong")/7 -> 0 | Y4: =IF(AND(AND(INDEX(BE_Tasks!$P$2:$P$53,MATCH("BE-A02",BE_Tasks!$A$2:$A$53,0))="Hoàn thành",INDEX(BE_Tasks!$Z$2:$Z$53,MATCH("BE-A02",BE_Tasks!$A$2:$A$53,0))="")),"Đủ điều kiện","Chờ phụ thuộc") -> Chờ phụ thuộc | Z4: =IF(AND(P4="Hoàn thành",OR(X4<1,Y4<>"Đủ điều kiện",AND(AE4="",AD4=""))),"Thiếu bước / phụ thuộc / bằng chứng","") | AG4: Mở task
A5: BE-A04 | B5: P1 | C5: 4 | D5: A | E5: B | F5: Idempotency, event store và adapter audit nền | G5: 5 | H5: 0 | J5: backend/src/core/** backend/contracts/core.* backend/tests/fixtures/A/** backend/tests/contracts/A/** backend/tests/e2e/platform-*/** backend/bootstrap.* backend/package* backend/lockfile .github/workflows/backend-* database/schema.sql database/migrations/* scripts/build-database.cjs backend/tests/e2e/release/** | K5: BE-A02 | M5: D09, D14 | N5: Store key+actor+route+request hash+kết quả; xử lý đang chạy, TTL và retry sau commit. EventPort append cùng transaction cho service; cơ chế lấy notifications sau CALL có checkpoint/dedupe và giới hạn bảo đảm được ghi rõ. AuditPort nhận đúng một target hợp lệ; procedure đã ghi audit/notification thì adapter không ghi lặp. | O5: Cùng key/payload trả kết quả cũ; khác payload 409; retry không nhân đôi tác dụng phụ. Kiểm thử crash trước/sau commit; không tuyên bố exactly-once cho kênh vận chuyển. | P5: Chưa làm | Q5: Chưa | R5: Chưa | S5: Chưa | T5: Chưa | U5: Chưa | V5: Chưa | W5: Chưa | X5: =COUNTIF(Q5:W5,"Xong")/7 -> 0 | Y5: =IF(AND(AND(INDEX(BE_Tasks!$P$2:$P$53,MATCH("BE-A02",BE_Tasks!$A$2:$A$53,0))="Hoàn thành",INDEX(BE_Tasks!$Z$2:$Z$53,MATCH("BE-A02",BE_Tasks!$A$2:$A$53,0))="")),"Đủ điều kiện","Chờ phụ thuộc") -> Chờ phụ thuộc | Z5: =IF(AND(P5="Hoàn thành",OR(X5<1,Y5<>"Đủ điều kiện",AND(AE5="",AD5=""))),"Thiếu bước / phụ thuộc / bằng chứng","") | AG5: Mở task
A6: BE-A05 | B6: P1 | C6: 5 | D6: A | E6: B | F6: Kho tệp riêng tư và quyền mở theo ngữ cảnh | G6: 8 | H6: 5 | I6: API-170, API-171, API-172, API-173, API-174 | J6: backend/src/modules/files/** backend/tests/files/** backend/contracts/files.* | K6: BE-A03, BE-A04 | M6: D05 | N6: Adapter kho tệp cấu hình qua môi trường; MIME magic, byte length, SHA-256 và ownership được server kiểm tra. FilePort hỗ trợ context resolver do B/C đăng ký riêng; không import service B/C vào files tạo vòng phụ thuộc. Proof đã tham chiếu bất biến, URL ngắn hạn và retention có chính sách D05. | O6: Proof nhà đúng 1–8 tệp, tối đa 5 MB/tệp; MIME giả/owner khác bị chặn. Không đọc được file bằng đoán ID; tệp đang được giữ không bị xóa vật lý. | P6: Chưa làm | Q6: Chưa | R6: Chưa | S6: Chưa | T6: Chưa | U6: Chưa | V6: Chưa | W6: Chưa | X6: =COUNTIF(Q6:W6,"Xong")/7 -> 0 | Y6: =IF(AND(AND(INDEX(BE_Tasks!$P$2:$P$53,MATCH("BE-A03",BE_Tasks!$A$2:$A$53,0))="Hoàn thành",INDEX(BE_Tasks!$Z$2:$Z$53,MATCH("BE-A03",BE_Tasks!$A$2:$A$53,0))=""),AND(INDEX(BE_Tasks!$P$2:$P$53,MATCH("BE-A04",BE_Tasks!$A$2:$A$53,0))="Hoàn thành",INDEX(BE_Tasks!$Z$2:$Z$53,MATCH("BE-A04",BE_Tasks!$A$2:$A$53,0))="")),"Đủ điều kiện","Chờ phụ thuộc") -> Chờ phụ thuộc | Z6: =IF(AND(P6="Hoàn thành",OR(X6<1,Y6<>"Đủ điều kiện",AND(AE6="",AD6=""))),"Thiếu bước / phụ thuộc / bằng chứng","") | AG6: Mở task
A7: BE-A06 | B7: P2 | C7: 6 | D7: A | E7: B | F7: Xác minh danh tính và cấp vai trò chủ trọ | G7: 5 | H7: 12 | I7: API-006, API-007, API-008, API-009, API-010, API-011, API-012, API-013, API-014, API-015, API-016, API-017 | J7: backend/src/modules/identity/** backend/tests/identity/** backend/contracts/identity.* | K7: BE-A05 | M7: D05 | N7: Một PENDING/người/loại; duyệt/từ chối có actor/time/reason. APPROVE landlord tạo dòng landlords trong cùng transaction; không tự duyệt nhà. Ghi audit và thông báo qua adapter đã chốt, giữ hồ sơ lịch sử. | O7: Hai lần nộp đồng thời không có hai PENDING; file của người khác bị chặn. Chủ trọ mới được cấp vai trò chỉ công khai nhà sau B05 xác minh riêng. | P7: Chưa làm | Q7: Chưa | R7: Chưa | S7: Chưa | T7: Chưa | U7: Chưa | V7: Chưa | W7: Chưa | X7: =COUNTIF(Q7:W7,"Xong")/7 -> 0 | Y7: =IF(AND(AND(INDEX(BE_Tasks!$P$2:$P$53,MATCH("BE-A05",BE_Tasks!$A$2:$A$53,0))="Hoàn thành",INDEX(BE_Tasks!$Z$2:$Z$53,MATCH("BE-A05",BE_Tasks!$A$2:$A$53,0))="")),"Đủ điều kiện","Chờ phụ thuộc") -> Chờ phụ thuộc | Z7: =IF(AND(P7="Hoàn thành",OR(X7<1,Y7<>"Đủ điều kiện",AND(AE7="",AD7=""))),"Thiếu bước / phụ thuộc / bằng chứng","") | AG7: Mở task
A8: BE-A07 | B8: P2 | C8: 7 | D8: A | E8: B | F8: OTP, reset mật khẩu và TokenPort | G8: 5 | H8: 5 | I8: API-022, API-023, API-024, API-025, API-026 | J8: backend/src/modules/identity/** backend/tests/identity/** backend/contracts/identity.* | K8: BE-A03, BE-A04 | M8: D01, D06 | N8: Hash/HMAC mã, hạn dùng, attempt, consumed/revoked; reset không lộ tài khoản tồn tại. Reset grant chỉ đổi mật khẩu đúng user và thu hồi phiên; phone uniqueness kiểm tra lại dưới khóa. TokenPort issue/consume hỗ trợ OCCUPANT_LINK và targetRoomTenantId trong transaction được C truyền vào. | O8: OTP sai/hết hạn/dùng lại đều thất bại đúng mã; không log/response OTP thực. C08 tiêu thụ token và gắn member trong cùng transaction, không gọi HTTP nội bộ. | P8: Chưa làm | Q8: Chưa | R8: Chưa | S8: Chưa | T8: Chưa | U8: Chưa | V8: Chưa | W8: Chưa | X8: =COUNTIF(Q8:W8,"Xong")/7 -> 0 | Y8: =IF(AND(AND(INDEX(BE_Tasks!$P$2:$P$53,MATCH("BE-A03",BE_Tasks!$A$2:$A$53,0))="Hoàn thành",INDEX(BE_Tasks!$Z$2:$Z$53,MATCH("BE-A03",BE_Tasks!$A$2:$A$53,0))=""),AND(INDEX(BE_Tasks!$P$2:$P$53,MATCH("BE-A04",BE_Tasks!$A$2:$A$53,0))="Hoàn thành",INDEX(BE_Tasks!$Z$2:$Z$53,MATCH("BE-A04",BE_Tasks!$A$2:$A$53,0))="")),"Đủ điều kiện","Chờ phụ thuộc") -> Chờ phụ thuộc | Z8: =IF(AND(P8="Hoàn thành",OR(X8<1,Y8<>"Đủ điều kiện",AND(AE8="",AD8=""))),"Thiếu bước / phụ thuộc / bằng chứng","") | AG8: Mở task
A9: BE-A08 | B9: P2 | C9: 8 | D9: A | E9: B | F9: Chat hỏi phòng và cổng hội thoại cho lịch xem | G9: 8 | H9: 7 | I9: API-076, API-077, API-078, API-079, API-080, API-081, API-082 | J9: backend/src/modules/messaging/** backend/src/modules/notifications/** backend/tests/messaging/** backend/contracts/messaging.* | K9: BE-A03, BE-A04, BE-B04 | M9: D03, D08 | N9: Get-or-create inquiry có unique/khóa theo D08; một context ghi/post/room, gộp peer chỉ khi đọc. Gửi TEXT/IMAGE chống trùng; cập nhật participant/read-state/last_message và sự kiện nguyên tử. Công bố ensureRoommateConversation(tx) cho B13; ConnectionPort kiểm tra accepted từ DB/fixture dù endpoint kết nối chưa hoàn thiện. | O9: Có tin người thuê về đúng phòng cho B08/B09; ROOMMATE không dùng hẹn chủ trọ. Chỉ participant được đọc/gửi; sender+client key không tạo trùng. | P9: Chưa làm | Q9: Chưa | R9: Chưa | S9: Chưa | T9: Chưa | U9: Chưa | V9: Chưa | W9: Chưa | X9: =COUNTIF(Q9:W9,"Xong")/7 -> 0 | Y9: =IF(AND(AND(INDEX(BE_Tasks!$P$2:$P$53,MATCH("BE-A03",BE_Tasks!$A$2:$A$53,0))="Hoàn thành",INDEX(BE_Tasks!$Z$2:$Z$53,MATCH("BE-A03",BE_Tasks!$A$2:$A$53,0))=""),AND(INDEX(BE_Tasks!$P$2:$P$53,MATCH("BE-A04",BE_Tasks!$A$2:$A$53,0))="Hoàn thành",INDEX(BE_Tasks!$Z$2:$Z$53,MATCH("BE-A04",BE_Tasks!$A$2:$A$53,0))=""),AND(INDEX(BE_Tasks!$P$2:$P$53,MATCH("BE-B04",BE_Tasks!$A$2:$A$53,0))="Hoàn thành",INDEX(BE_Tasks!$Z$2:$Z$53,MATCH("BE-B04",BE_Tasks!$A$2:$A$53,0))="")),"Đủ điều kiện","Chờ phụ thuộc") -> Chờ phụ thuộc | Z9: =IF(AND(P9="Hoàn thành",OR(X9<1,Y9<>"Đủ điều kiện",AND(AE9="",AD9=""))),"Thiếu bước / phụ thuộc / bằng chứng","") | AG9: Mở task
A10: BE-A09 | B10: P3 | C10: 9 | D10: A | E10: B | F10: Feed thông báo, bộ đếm và đánh dấu đọc | G10: 3 | H10: 4 | I10: API-086, API-087, API-088, API-089 | J10: backend/src/modules/messaging/** backend/src/modules/notifications/** backend/tests/messaging/** backend/contracts/messaging.* | K10: BE-A04, BE-A08 | N10: Feed scoped user, counts, read một/tất cả đến mốc server. Chống event_key trùng, mở tài nguyên vẫn kiểm tra quyền lại. Chuẩn hóa thông báo do procedure và service phát, giữ popup là trạng thái UI. | O10: Đọc thông báo của user khác bị chặn; read-all không đọc nhầm sự kiện đến sau mốc. Tắt realtime không làm mất thông báo đã commit. | P10: Chưa làm | Q10: Chưa | R10: Chưa | S10: Chưa | T10: Chưa | U10: Chưa | V10: Chưa | W10: Chưa | X10: =COUNTIF(Q10:W10,"Xong")/7 -> 0 | Y10: =IF(AND(AND(INDEX(BE_Tasks!$P$2:$P$53,MATCH("BE-A04",BE_Tasks!$A$2:$A$53,0))="Hoàn thành",INDEX(BE_Tasks!$Z$2:$Z$53,MATCH("BE-A04",BE_Tasks!$A$2:$A$53,0))=""),AND(INDEX(BE_Tasks!$P$2:$P$53,MATCH("BE-A08",BE_Tasks!$A$2:$A$53,0))="Hoàn thành",INDEX(BE_Tasks!$Z$2:$Z$53,MATCH("BE-A08",BE_Tasks!$A$2:$A$53,0))="")),"Đủ điều kiện","Chờ phụ thuộc") -> Chờ phụ thuộc | Z10: =IF(AND(P10="Hoàn thành",OR(X10<1,Y10<>"Đủ điều kiện",AND(AE10="",AD10=""))),"Thiếu bước / phụ thuộc / bằng chứng","") | AG10: Mở task
A11: BE-A10 | B11: P4 | C11: 10 | D11: A | E11: B | F11: Hóa đơn nháp và snapshot giá/người trả | G11: 5 | H11: 4 | I11: API-145, API-146, API-147, API-148 | J11: backend/src/modules/billing/** backend/tests/billing/** backend/contracts/billing.* | K11: BE-A04, BE-B03, BE-C02 | L11: BE-C07 | M11: D12 | N11: Unique contract+kỳ chưa hủy; server tính quantity, meter, tiền thuê và giảm trừ bằng decimal. Snapshot revision, representative/payer và số ACTIVE trong cùng transaction đọc hợp đồng. Chỉ sửa DRAFT; hợp đồng ACTIVE thật cho E2E được bàn giao khi C07 hoàn thành. | O11: Override=0 giữ 0; người PLANNED không tính dịch vụ theo người; chỉ số cuối<đầu bị chặn. Đổi đại diện/giá sau lập không đổi snapshot hóa đơn cũ. | P11: Chưa làm | Q11: Chưa | R11: Chưa | S11: Chưa | T11: Chưa | U11: Chưa | V11: Chưa | W11: Chưa | X11: =COUNTIF(Q11:W11,"Xong")/7 -> 0 | Y11: =IF(AND(AND(INDEX(BE_Tasks!$P$2:$P$53,MATCH("BE-A04",BE_Tasks!$A$2:$A$53,0))="Hoàn thành",INDEX(BE_Tasks!$Z$2:$Z$53,MATCH("BE-A04",BE_Tasks!$A$2:$A$53,0))=""),AND(INDEX(BE_Tasks!$P$2:$P$53,MATCH("BE-B03",BE_Tasks!$A$2:$A$53,0))="Hoàn thành",INDEX(BE_Tasks!$Z$2:$Z$53,MATCH("BE-B03",BE_Tasks!$A$2:$A$53,0))=""),AND(INDEX(BE_Tasks!$P$2:$P$53,MATCH("BE-C02",BE_Tasks!$A$2:$A$53,0))="Hoàn thành",INDEX(BE_Tasks!$Z$2:$Z$53,MATCH("BE-C02",BE_Tasks!$A$2:$A$53,0))=""),AND(INDEX(BE_Tasks!$P$2:$P$53,MATCH("BE-C07",BE_Tasks!$A$2:$A$53,0))="Hoàn thành",INDEX(BE_Tasks!$Z$2:$Z$53,MATCH("BE-C07",BE_Tasks!$A$2:$A$53,0))="")),"Đủ điều kiện","Chờ phụ thuộc") -> Chờ phụ thuộc | Z11: =IF(AND(P11="Hoàn thành",OR(X11<1,Y11<>"Đủ điều kiện",AND(AE11="",AD11=""))),"Thiếu bước / phụ thuộc / bằng chứng","") | AG11: Mở task
A12: BE-A11 | B12: P4 | C12: 11 | D12: A | E12: B | F12: Thẻ lịch, chat bạn ghép và chia sẻ đúng tin | G12: 5 | H12: 3 | I12: API-083, API-084, API-085 | J12: backend/src/modules/messaging/** backend/src/modules/notifications/** backend/tests/messaging/** backend/contracts/messaging.* | K12: BE-A08, BE-B04, BE-C02 | L12: BE-B13, BE-B09 | M12: D03 | N12: Timeline lấy viewing/proposal theo conversation có quyền; share giữ đúng postId. ROOMMATE chỉ mở/gửi khi accepted còn hiệu lực; inactive post trả unavailable không lộ ảnh/tiêu đề. B13 dùng ensureRoommateConversation đã có ở A08; hai phần không phụ thuộc nhau theo vòng HTTP. | O12: Accept kết nối xong mở cùng conversation; share không tạo join/hold/lịch. Bài ẩn không tự đổi sang bài khác cùng phòng; chat inquiry và roommate không lẫn thẻ lịch. | P12: Chưa làm | Q12: Chưa | R12: Chưa | S12: Chưa | T12: Chưa | U12: Chưa | V12: Chưa | W12: Chưa | X12: =COUNTIF(Q12:W12,"Xong")/7 -> 0 | Y12: =IF(AND(AND(INDEX(BE_Tasks!$P$2:$P$53,MATCH("BE-A08",BE_Tasks!$A$2:$A$53,0))="Hoàn thành",INDEX(BE_Tasks!$Z$2:$Z$53,MATCH("BE-A08",BE_Tasks!$A$2:$A$53,0))=""),AND(INDEX(BE_Tasks!$P$2:$P$53,MATCH("BE-B04",BE_Tasks!$A$2:$A$53,0))="Hoàn thành",INDEX(BE_Tasks!$Z$2:$Z$53,MATCH("BE-B04",BE_Tasks!$A$2:$A$53,0))=""),AND(INDEX(BE_Tasks!$P$2:$P$53,MATCH("BE-C02",BE_Tasks!$A$2:$A$53,0))="Hoàn thành",INDEX(BE_Tasks!$Z$2:$Z$53,MATCH("BE-C02",BE_Tasks!$A$2:$A$53,0))=""),AND(INDEX(BE_Tasks!$P$2:$P$53,MATCH("BE-B13",BE_Tasks!$A$2:$A$53,0))="Hoàn thành",INDEX(BE_Tasks!$Z$2:$Z$53,MATCH("BE-B13",BE_Tasks!$A$2:$A$53,0))=""),AND(INDEX(BE_Tasks!$P$2:$P$53,MATCH("BE-B09",BE_Tasks!$A$2:$A$53,0))="Hoàn thành",INDEX(BE_Tasks!$Z$2:$Z$53,MATCH("BE-B09",BE_Tasks!$A$2:$A$53,0))="")),"Đủ điều kiện","Chờ phụ thuộc") -> Chờ phụ thuộc | Z12: =IF(AND(P12="Hoàn thành",OR(X12<1,Y12<>"Đủ điều kiện",AND(AE12="",AD12=""))),"Thiếu bước / phụ thuộc / bằng chứng","") | AG12: Mở task
A13: BE-A12 | B13: P4 | C13: 12 | D13: A | E13: B | F13: Quản trị tài khoản và tra cứu audit | G13: 5 | H13: 6 | I13: API-161, API-162, API-163, API-164, API-168, API-169 | J13: backend/src/modules/account-admin/** backend/src/modules/audit/** backend/src/modules/admin-dashboard/** backend/tests/account-admin/** | K13: BE-A03, BE-A04 | N13: Lock/unlock có reason, audit và revoke session; không xóa cư trú/nghĩa vụ. Audit chỉ đọc, lọc đối tượng và che secret/PII khỏi snapshot. Không sửa source SQL nhà của B để tính quyền; view hiệu lực đã xét trạng thái user. | O13: Tài khoản bị khóa mất quyền trên mọi module qua cùng middleware. Khóa landlord làm public view mất quyền, nhưng hợp đồng/người ở cũ được giữ. | P13: Chưa làm | Q13: Chưa | R13: Chưa | S13: Chưa | T13: Chưa | U13: Chưa | V13: Chưa | W13: Chưa | X13: =COUNTIF(Q13:W13,"Xong")/7 -> 0 | Y13: =IF(AND(AND(INDEX(BE_Tasks!$P$2:$P$53,MATCH("BE-A03",BE_Tasks!$A$2:$A$53,0))="Hoàn thành",INDEX(BE_Tasks!$Z$2:$Z$53,MATCH("BE-A03",BE_Tasks!$A$2:$A$53,0))=""),AND(INDEX(BE_Tasks!$P$2:$P$53,MATCH("BE-A04",BE_Tasks!$A$2:$A$53,0))="Hoàn thành",INDEX(BE_Tasks!$Z$2:$Z$53,MATCH("BE-A04",BE_Tasks!$A$2:$A$53,0))="")),"Đủ điều kiện","Chờ phụ thuộc") -> Chờ phụ thuộc | Z13: =IF(AND(P13="Hoàn thành",OR(X13<1,Y13<>"Đủ điều kiện",AND(AE13="",AD13=""))),"Thiếu bước / phụ thuộc / bằng chứng","") | AG13: Mở task
A14: BE-A13 | B14: P5 | C14: 13 | D14: A | E14: B | F14: Phát hành, thu đủ, hủy và thay hóa đơn | G14: 5 | H14: 4 | I14: API-149, API-150, API-151, API-152 | J14: backend/src/modules/billing/** backend/tests/billing/** backend/contracts/billing.* | K14: BE-A10 | M14: D12 | N14: Issue DRAFT có dòng tiền → UNPAID; PAID có người ghi nhận/time; hủy chưa thu có lý do. Replacement giữ cùng contract/kỳ và liên kết bản đã hủy; không sửa lines phát hành. JOB04 chuyển UNPAID quá due_date VN sang OVERDUE, chạy lặp an toàn; giữ quyền người trả cũ sau bàn giao, không giả có issued_at riêng. | O14: Hai lần thu cùng khóa không tạo thêm thu tiền; PAID/CANCELLED không sửa. Kỳ mới lấy đại diện hiện tại, kỳ cũ vẫn đúng payer. | P14: Chưa làm | Q14: Chưa | R14: Chưa | S14: Chưa | T14: Chưa | U14: Chưa | V14: Chưa | W14: Chưa | X14: =COUNTIF(Q14:W14,"Xong")/7 -> 0 | Y14: =IF(AND(AND(INDEX(BE_Tasks!$P$2:$P$53,MATCH("BE-A10",BE_Tasks!$A$2:$A$53,0))="Hoàn thành",INDEX(BE_Tasks!$Z$2:$Z$53,MATCH("BE-A10",BE_Tasks!$A$2:$A$53,0))="")),"Đủ điều kiện","Chờ phụ thuộc") -> Chờ phụ thuộc | Z14: =IF(AND(P14="Hoàn thành",OR(X14<1,Y14<>"Đủ điều kiện",AND(AE14="",AD14=""))),"Thiếu bước / phụ thuộc / bằng chứng","") | AG14: Mở task
A15: BE-A14 | B15: P5 | C15: 14 | D15: A | E15: B | F15: SSE có xác thực và nối lại sự kiện | G15: 5 | H15: 1 | I15: API-090 | J15: backend/src/modules/messaging/** backend/src/modules/notifications/** backend/tests/messaging/** backend/contracts/messaging.* | K15: BE-A04, BE-A09 | M15: D09 | N15: Auth phiên, Last-Event-ID, replay trong cửa sổ lưu, recipient scope và dedupe eventId. Phát sau commit; reconnect không coi popup đã đóng là đã đọc. Tải trọng tối thiểu rồi client fetch resource; kiểm tra session revoked khi stream còn mở. | O15: Mất kết nối/retry không mất nguồn dữ liệu gốc và không lộ sự kiện người khác. Crash/delivery lặp vẫn cho client dedupe và đọc lại feed. | P15: Chưa làm | Q15: Chưa | R15: Chưa | S15: Chưa | T15: Chưa | U15: Chưa | V15: Chưa | W15: Chưa | X15: =COUNTIF(Q15:W15,"Xong")/7 -> 0 | Y15: =IF(AND(AND(INDEX(BE_Tasks!$P$2:$P$53,MATCH("BE-A04",BE_Tasks!$A$2:$A$53,0))="Hoàn thành",INDEX(BE_Tasks!$Z$2:$Z$53,MATCH("BE-A04",BE_Tasks!$A$2:$A$53,0))=""),AND(INDEX(BE_Tasks!$P$2:$P$53,MATCH("BE-A09",BE_Tasks!$A$2:$A$53,0))="Hoàn thành",INDEX(BE_Tasks!$Z$2:$Z$53,MATCH("BE-A09",BE_Tasks!$A$2:$A$53,0))="")),"Đủ điều kiện","Chờ phụ thuộc") -> Chờ phụ thuộc | Z15: =IF(AND(P15="Hoàn thành",OR(X15<1,Y15<>"Đủ điều kiện",AND(AE15="",AD15=""))),"Thiếu bước / phụ thuộc / bằng chứng","") | AG15: Mở task
A16: BE-A15 | B16: P6 | C16: 15 | D16: A | E16: B | F16: Retention, audit mở rộng và dashboard quản trị | G16: 3 | H16: 1 | I16: API-176 | J16: backend/src/core/** backend/contracts/core.* backend/tests/fixtures/A/** backend/tests/contracts/A/** backend/tests/e2e/platform-*/** backend/bootstrap.* backend/package* backend/lockfile .github/workflows/backend-* backend/src/modules/account-admin/** backend/src/modules/audit/** backend/src/modules/admin-dashboard/** backend/tests/account-admin/** database/schema.sql database/migrations/* scripts/build-database.cjs backend/tests/e2e/release/** | K16: BE-A05, BE-A12, BE-A14 | L16: BE-B14 | M16: D04, D05, D14 | N16: D14 có migration/adapters và contract target mới trước B16; không gán nhầm review thành post. JOB05 dọn đúng scope/hạn lưu, tệp bị giữ làm chứng cứ được bảo toàn. Admin dashboard đếm riêng account identity/house proof/posts/reports; flags email/push chỉ bật khi provider được chốt. | O16: Job lặp an toàn, không xóa bằng chứng đang tham chiếu. Dashboard không công khai PII; số liệu có asOf và nguồn từng module. | P16: Chưa làm | Q16: Chưa | R16: Chưa | S16: Chưa | T16: Chưa | U16: Chưa | V16: Chưa | W16: Chưa | X16: =COUNTIF(Q16:W16,"Xong")/7 -> 0 | Y16: =IF(AND(AND(INDEX(BE_Tasks!$P$2:$P$53,MATCH("BE-A05",BE_Tasks!$A$2:$A$53,0))="Hoàn thành",INDEX(BE_Tasks!$Z$2:$Z$53,MATCH("BE-A05",BE_Tasks!$A$2:$A$53,0))=""),AND(INDEX(BE_Tasks!$P$2:$P$53,MATCH("BE-A12",BE_Tasks!$A$2:$A$53,0))="Hoàn thành",INDEX(BE_Tasks!$Z$2:$Z$53,MATCH("BE-A12",BE_Tasks!$A$2:$A$53,0))=""),AND(INDEX(BE_Tasks!$P$2:$P$53,MATCH("BE-A14",BE_Tasks!$A$2:$A$53,0))="Hoàn thành",INDEX(BE_Tasks!$Z$2:$Z$53,MATCH("BE-A14",BE_Tasks!$A$2:$A$53,0))=""),AND(INDEX(BE_Tasks!$P$2:$P$53,MATCH("BE-B14",BE_Tasks!$A$2:$A$53,0))="Hoàn thành",INDEX(BE_Tasks!$Z$2:$Z$53,MATCH("BE-B14",BE_Tasks!$A$2:$A$53,0))="")),"Đủ điều kiện","Chờ phụ thuộc") -> Chờ phụ thuộc | Z16: =IF(AND(P16="Hoàn thành",OR(X16<1,Y16<>"Đủ điều kiện",AND(AE16="",AD16=""))),"Thiếu bước / phụ thuộc / bằng chứng","") | AG16: Mở task
A17: BE-A16 | B17: P7 | C17: 16 | D17: A | E17: B | F17: Kiểm thử bảo mật, hóa đơn và lỗi hạ tầng | G17: 5 | H17: 0 | J17: backend/src/core/** backend/contracts/core.* backend/tests/fixtures/A/** backend/tests/contracts/A/** backend/tests/e2e/platform-*/** backend/bootstrap.* backend/package* backend/lockfile .github/workflows/backend-* backend/src/modules/billing/** backend/tests/billing/** backend/contracts/billing.* backend/src/modules/messaging/** backend/src/modules/notifications/** backend/tests/messaging/** backend/contracts/messaging.* | K17: BE-A15 | N17: Test scope chéo ID, nhiều vai trò, revoke/LOCKED, OTP và tài liệu riêng. Test idempotency sau commit/timeout, outbox/SSE reconnect và invoice snapshot. Ghi bằng chứng chạy CI, migration mới và cách rollback/retry về mặt vận hành. | O17: QA10/11/12/15/16 đạt trên DB tạm và storage test. Không dùng localStorage wireframe làm bằng chứng backend đã chạy. | P17: Chưa làm | Q17: Chưa | R17: Chưa | S17: Chưa | T17: Chưa | U17: Chưa | V17: Chưa | W17: Chưa | X17: =COUNTIF(Q17:W17,"Xong")/7 -> 0 | Y17: =IF(AND(AND(INDEX(BE_Tasks!$P$2:$P$53,MATCH("BE-A15",BE_Tasks!$A$2:$A$53,0))="Hoàn thành",INDEX(BE_Tasks!$Z$2:$Z$53,MATCH("BE-A15",BE_Tasks!$A$2:$A$53,0))="")),"Đủ điều kiện","Chờ phụ thuộc") -> Chờ phụ thuộc | Z17: =IF(AND(P17="Hoàn thành",OR(X17<1,Y17<>"Đủ điều kiện",AND(AE17="",AD17=""))),"Thiếu bước / phụ thuộc / bằng chứng","") | AG17: Mở task
A18: BE-A17 | B18: P7 | C18: 17 | D18: A | E18: B | F18: Tích hợp bản bàn giao Backend | G18: 3 | H18: 0 | J18: database/schema.sql database/migrations/* scripts/build-database.cjs backend/tests/e2e/release/** | K18: BE-A16, BE-B19, BE-C16 | N18: Tái sinh schema từ toàn bộ source, chốt thứ tự migration; test tạo mới/nâng cấp trên DB tạm. Đối chiếu 176 API có đúng một task/module owner, gom collection/API docs và hướng dẫn chạy. Xác nhận toàn bộ gate; ghi các quyết định ngoài phạm vi còn hoãn, không gọi backend hoàn tất nếu endpoint tương ứng chưa đạt. | O18: Feature CI, DB check, contract tests và E2E ba lane đều xanh. Không ai sửa tay schema sinh ra; không deploy hoặc áp dụng migration DB thật trong task tài liệu này. | P18: Chưa làm | Q18: Chưa | R18: Chưa | S18: Chưa | T18: Chưa | U18: Chưa | V18: Chưa | W18: Chưa | X18: =COUNTIF(Q18:W18,"Xong")/7 -> 0 | Y18: =IF(AND(AND(INDEX(BE_Tasks!$P$2:$P$53,MATCH("BE-A16",BE_Tasks!$A$2:$A$53,0))="Hoàn thành",INDEX(BE_Tasks!$Z$2:$Z$53,MATCH("BE-A16",BE_Tasks!$A$2:$A$53,0))=""),AND(INDEX(BE_Tasks!$P$2:$P$53,MATCH("BE-B19",BE_Tasks!$A$2:$A$53,0))="Hoàn thành",INDEX(BE_Tasks!$Z$2:$Z$53,MATCH("BE-B19",BE_Tasks!$A$2:$A$53,0))=""),AND(INDEX(BE_Tasks!$P$2:$P$53,MATCH("BE-C16",BE_Tasks!$A$2:$A$53,0))="Hoàn thành",INDEX(BE_Tasks!$Z$2:$Z$53,MATCH("BE-C16",BE_Tasks!$A$2:$A$53,0))="")),"Đủ điều kiện","Chờ phụ thuộc") -> Chờ phụ thuộc | Z18: =IF(AND(P18="Hoàn thành",OR(X18<1,Y18<>"Đủ điều kiện",AND(AE18="",AD18=""))),"Thiếu bước / phụ thuộc / bằng chứng","") | AG18: Mở task
A19: BE-B01 | B19: P0 | C19: 1 | D19: B | E19: C | F19: Chốt module nhà/tin/lịch và dữ liệu bàn giao | G19: 3 | H19: 0 | J19: backend/src/modules/properties/** backend/src/modules/house-rights/** backend/tests/properties/** backend/tests/fixtures/B/** backend/tests/contracts/B/** backend/tests/e2e/property-*/** backend/contracts/properties.* backend/src/modules/posts/** backend/tests/posts/** backend/contracts/posts.* backend/src/modules/services/** backend/tests/services/** backend/contracts/services.* backend/src/modules/viewings/** backend/tests/viewings/** backend/tests/e2e/viewing-contract/** backend/contracts/viewings.* backend/src/modules/roommates/** backend/tests/roommates/** backend/contracts/roommates.* | M19: D02, D07, D08, D13 | N19: Phân biệt postId/roomId, quyền nhà, capacity load, quote service và trạng thái kết nối. Tạo fixture trong backend/tests/fixtures/B/**; không sửa seed chung của A/C. Chốt cổng IF-ROOM/IF-SERVICE/IF-CONNECTION với A02/C01; các loại payload không đổi âm thầm. | O19: Consumer có thể chạy contract test với fixture chưa cần endpoint thật. D02/D07/D08/D13 được ghi rõ người đề xuất/người chốt và route bị ảnh hưởng. | P19: Chưa làm | Q19: Chưa | R19: Chưa | S19: Chưa | T19: Chưa | U19: Chưa | V19: Chưa | W19: Chưa | X19: =COUNTIF(Q19:W19,"Xong")/7 -> 0 | Y19: =IF(TRUE,"Đủ điều kiện","Chờ phụ thuộc") -> Đủ điều kiện | Z19: =IF(AND(P19="Hoàn thành",OR(X19<1,Y19<>"Đủ điều kiện",AND(AE19="",AD19=""))),"Thiếu bước / phụ thuộc / bằng chứng","") | AG19: Mở task
A20: BE-B02 | B20: P1 | C20: 2 | D20: B | E20: C | F20: Nhà/phòng CRUD và sức chứa | G20: 8 | H20: 8 | I20: API-029, API-030, API-031, API-032, API-042, API-043, API-044, API-045 | J20: backend/src/modules/properties/** backend/src/modules/house-rights/** backend/tests/properties/** backend/tests/fixtures/B/** backend/tests/contracts/B/** backend/tests/e2e/property-*/** backend/contracts/properties.* | K20: BE-A02, BE-B01 | L20: BE-A03 | N20: Nhà create idempotency, update row_version/verification_version đúng procedure. Mã phòng duy nhất/nhà; giá và diện tích hợp lệ, status suy từ người/hợp đồng. Capacity gọi sp_set_room_capacity; procedure nằm workflows.sql của C, cần đổi thì gửi C patch request. | O20: Không đặt phòng có ACTIVE thành AVAILABLE; không giảm dưới ACTIVE+PLANNED mở+hold còn hạn. Dùng auth middleware A khi tích hợp, không hardcode user Quân/demo. | P20: Chưa làm | Q20: Chưa | R20: Chưa | S20: Chưa | T20: Chưa | U20: Chưa | V20: Chưa | W20: Chưa | X20: =COUNTIF(Q20:W20,"Xong")/7 -> 0 | Y20: =IF(AND(AND(INDEX(BE_Tasks!$P$2:$P$53,MATCH("BE-A02",BE_Tasks!$A$2:$A$53,0))="Hoàn thành",INDEX(BE_Tasks!$Z$2:$Z$53,MATCH("BE-A02",BE_Tasks!$A$2:$A$53,0))=""),AND(INDEX(BE_Tasks!$P$2:$P$53,MATCH("BE-B01",BE_Tasks!$A$2:$A$53,0))="Hoàn thành",INDEX(BE_Tasks!$Z$2:$Z$53,MATCH("BE-B01",BE_Tasks!$A$2:$A$53,0))=""),AND(INDEX(BE_Tasks!$P$2:$P$53,MATCH("BE-A03",BE_Tasks!$A$2:$A$53,0))="Hoàn thành",INDEX(BE_Tasks!$Z$2:$Z$53,MATCH("BE-A03",BE_Tasks!$A$2:$A$53,0))="")),"Đủ điều kiện","Chờ phụ thuộc") -> Chờ phụ thuộc | Z20: =IF(AND(P20="Hoàn thành",OR(X20<1,Y20<>"Đủ điều kiện",AND(AE20="",AD20=""))),"Thiếu bước / phụ thuộc / bằng chứng","") | AG20: Mở task
A21: BE-B03 | B21: P1 | C21: 3 | D21: B | E21: C | F21: Dịch vụ nhà/phòng và giá hiệu lực | G21: 5 | H21: 9 | I21: API-049, API-137, API-138, API-139, API-140, API-141, API-142, API-143, API-144 | J21: backend/src/modules/services/** backend/tests/services/** backend/contracts/services.* | K21: BE-A02, BE-B02 | N21: Danh mục đúng rental_services hiện tại, không giả có code/active; dịch vụ riêng catalog_service_id null. Upsert đúng nhà/phòng, active cả hai cấp; null kế thừa, override 0 giữ 0. Công bố ServiceQuotePort có thể đọc bằng connection/UoW của consumer để chốt invoice snapshot. | O21: Không gán dịch vụ nhà khác; giá/phương pháp override hợp lệ. Đổi cấu hình không cập nhật dòng invoice đã có. | P21: Chưa làm | Q21: Chưa | R21: Chưa | S21: Chưa | T21: Chưa | U21: Chưa | V21: Chưa | W21: Chưa | X21: =COUNTIF(Q21:W21,"Xong")/7 -> 0 | Y21: =IF(AND(AND(INDEX(BE_Tasks!$P$2:$P$53,MATCH("BE-A02",BE_Tasks!$A$2:$A$53,0))="Hoàn thành",INDEX(BE_Tasks!$Z$2:$Z$53,MATCH("BE-A02",BE_Tasks!$A$2:$A$53,0))=""),AND(INDEX(BE_Tasks!$P$2:$P$53,MATCH("BE-B02",BE_Tasks!$A$2:$A$53,0))="Hoàn thành",INDEX(BE_Tasks!$Z$2:$Z$53,MATCH("BE-B02",BE_Tasks!$A$2:$A$53,0))="")),"Đủ điều kiện","Chờ phụ thuộc") -> Chờ phụ thuộc | Z21: =IF(AND(P21="Hoàn thành",OR(X21<1,Y21<>"Đủ điều kiện",AND(AE21="",AD21=""))),"Thiếu bước / phụ thuộc / bằng chứng","") | AG21: Mở task
A22: BE-B04 | B22: P1 | C22: 4 | D22: B | E22: C | F22: Cổng đọc nhà/phòng và kết nối cho A/C | G22: 3 | H22: 0 | J22: backend/src/modules/properties/** backend/src/modules/house-rights/** backend/tests/properties/** backend/tests/fixtures/B/** backend/tests/contracts/B/** backend/tests/e2e/property-*/** backend/contracts/properties.* backend/src/modules/services/** backend/tests/services/** backend/contracts/services.* backend/src/modules/roommates/** backend/tests/roommates/** backend/contracts/roommates.* | K22: BE-B02, BE-B03 | N22: RoomSnapshot có capacity/status/effectiveRight/currentLoad, không chứa PII cư dân. ConnectionPort đọc accepted/not-ended bằng transaction được truyền; dữ liệu test riêng dù B13 chưa tạo endpoint. ServiceQuotePort và FileContext resolver không tạo import vòng; injection ở composition root do A quản lý. | O22: Contract tests chạy cùng bộ fixture với mock B01. C vẫn recheck quyền/capacity dưới khóa trong procedure, không dùng snapshot cũ làm quyền thuê. | P22: Chưa làm | Q22: Chưa | R22: Chưa | S22: Chưa | T22: Chưa | U22: Chưa | V22: Chưa | W22: Chưa | X22: =COUNTIF(Q22:W22,"Xong")/7 -> 0 | Y22: =IF(AND(AND(INDEX(BE_Tasks!$P$2:$P$53,MATCH("BE-B02",BE_Tasks!$A$2:$A$53,0))="Hoàn thành",INDEX(BE_Tasks!$Z$2:$Z$53,MATCH("BE-B02",BE_Tasks!$A$2:$A$53,0))=""),AND(INDEX(BE_Tasks!$P$2:$P$53,MATCH("BE-B03",BE_Tasks!$A$2:$A$53,0))="Hoàn thành",INDEX(BE_Tasks!$Z$2:$Z$53,MATCH("BE-B03",BE_Tasks!$A$2:$A$53,0))="")),"Đủ điều kiện","Chờ phụ thuộc") -> Chờ phụ thuộc | Z22: =IF(AND(P22="Hoàn thành",OR(X22<1,Y22<>"Đủ điều kiện",AND(AE22="",AD22=""))),"Thiếu bước / phụ thuộc / bằng chứng","") | AG22: Mở task
A23: BE-B05 | B23: P2 | C23: 5 | D23: B | E23: C | F23: Xác minh quyền nhà và trạng thái hiệu lực | G23: 8 | H23: 9 | I23: API-033, API-034, API-035, API-036, API-037, API-038, API-039, API-040, API-041 | J23: backend/src/modules/properties/** backend/src/modules/house-rights/** backend/tests/properties/** backend/tests/fixtures/B/** backend/tests/contracts/B/** backend/tests/e2e/property-*/** backend/contracts/properties.* database/source/house-rights.sql database/source/post-review-quota.sql database/source/viewing-proposals.sql backend/tests/sql-property/** | K23: BE-B04, BE-A05 | M23: D05 | N23: Nộp/rút/duyệt/từ chối/thu hồi đúng procedure, đủ loại giấy theo OWNER/AUTHORIZED/SUBLESSOR. Ngày hiệu lực VN, định danh/version khớp; pending không tự làm mất quyền cũ. Dùng effective view khi đọc; mất quyền chặn công khai/thuê mới nhưng giữ lịch sử. | O23: Không có quyền chỉ nhờ account landlord được duyệt; admin cần evidenceChecked=true. Đổi định danh/rút/hết hạn/thu hồi giữ tệp bất biến và audit. | P23: Chưa làm | Q23: Chưa | R23: Chưa | S23: Chưa | T23: Chưa | U23: Chưa | V23: Chưa | W23: Chưa | X23: =COUNTIF(Q23:W23,"Xong")/7 -> 0 | Y23: =IF(AND(AND(INDEX(BE_Tasks!$P$2:$P$53,MATCH("BE-B04",BE_Tasks!$A$2:$A$53,0))="Hoàn thành",INDEX(BE_Tasks!$Z$2:$Z$53,MATCH("BE-B04",BE_Tasks!$A$2:$A$53,0))=""),AND(INDEX(BE_Tasks!$P$2:$P$53,MATCH("BE-A05",BE_Tasks!$A$2:$A$53,0))="Hoàn thành",INDEX(BE_Tasks!$Z$2:$Z$53,MATCH("BE-A05",BE_Tasks!$A$2:$A$53,0))="")),"Đủ điều kiện","Chờ phụ thuộc") -> Chờ phụ thuộc | Z23: =IF(AND(P23="Hoàn thành",OR(X23<1,Y23<>"Đủ điều kiện",AND(AE23="",AD23=""))),"Thiếu bước / phụ thuộc / bằng chứng","") | AG23: Mở task
A24: BE-B06 | B24: P2 | C24: 6 | D24: B | E24: C | F24: Gửi tin kèm ảnh nguyên tử và kiểm duyệt | G24: 8 | H24: 8 | I24: API-047, API-050, API-051, API-052, API-053, API-054, API-055, API-056 | J24: backend/src/modules/posts/** backend/tests/posts/** backend/contracts/posts.* database/source/house-rights.sql database/source/post-review-quota.sql database/source/viewing-proposals.sql backend/tests/sql-property/** | K24: BE-B05, BE-A04, BE-A05 | M24: D07 | N24: sp_submit_post nhận/ghi ảnh+amenities cùng transaction, content_version và quota 3 slot đúng hiện tại. Edit giữ roomId; pending edit không chiếm thêm lượt; moderate/hide/restore theo đúng postId. Các /admin/posts ở module posts; không sửa account-admin controller của A. | O24: 4 submit tranh slot chỉ có tối đa 3 pending; lỗi ảnh rollback cả bài và slot. Duyệt/restore yêu cầu quyền nhà hiệu lực; không ảnh hưởng các tin khác của phòng. | P24: Chưa làm | Q24: Chưa | R24: Chưa | S24: Chưa | T24: Chưa | U24: Chưa | V24: Chưa | W24: Chưa | X24: =COUNTIF(Q24:W24,"Xong")/7 -> 0 | Y24: =IF(AND(AND(INDEX(BE_Tasks!$P$2:$P$53,MATCH("BE-B05",BE_Tasks!$A$2:$A$53,0))="Hoàn thành",INDEX(BE_Tasks!$Z$2:$Z$53,MATCH("BE-B05",BE_Tasks!$A$2:$A$53,0))=""),AND(INDEX(BE_Tasks!$P$2:$P$53,MATCH("BE-A04",BE_Tasks!$A$2:$A$53,0))="Hoàn thành",INDEX(BE_Tasks!$Z$2:$Z$53,MATCH("BE-A04",BE_Tasks!$A$2:$A$53,0))=""),AND(INDEX(BE_Tasks!$P$2:$P$53,MATCH("BE-A05",BE_Tasks!$A$2:$A$53,0))="Hoàn thành",INDEX(BE_Tasks!$Z$2:$Z$53,MATCH("BE-A05",BE_Tasks!$A$2:$A$53,0))="")),"Đủ điều kiện","Chờ phụ thuộc") -> Chờ phụ thuộc | Z24: =IF(AND(P24="Hoàn thành",OR(X24<1,Y24<>"Đủ điều kiện",AND(AE24="",AD24=""))),"Thiếu bước / phụ thuộc / bằng chứng","") | AG24: Mở task
A25: BE-B07 | B25: P2 | C25: 7 | D25: B | E25: C | F25: Tìm phòng, chi tiết và lưu tin công khai | G25: 5 | H25: 6 | I25: API-046, API-057, API-058, API-059, API-060, API-061 | J25: backend/src/modules/posts/** backend/tests/posts/** backend/contracts/posts.* backend/src/modules/properties/** backend/src/modules/house-rights/** backend/tests/properties/** backend/tests/fixtures/B/** backend/tests/contracts/B/** backend/tests/e2e/property-*/** backend/contracts/properties.* | K25: BE-B06 | N25: Lọc/search/paging/sort whitelist; không lộ PII người ở trong room detail. Lưu theo postId; tin ẩn trả placeholder/404, không chuyển sang tin khác cùng phòng. Bàn giao PublicPostPort để A share card và tạo inquiry từ postId. | O25: Hết quyền nhà ẩn ngay không chờ job; khám phá loại OCCUPIED đúng rule. Public JSON không có residents/CCCD/tin chưa duyệt. | P25: Chưa làm | Q25: Chưa | R25: Chưa | S25: Chưa | T25: Chưa | U25: Chưa | V25: Chưa | W25: Chưa | X25: =COUNTIF(Q25:W25,"Xong")/7 -> 0 | Y25: =IF(AND(AND(INDEX(BE_Tasks!$P$2:$P$53,MATCH("BE-B06",BE_Tasks!$A$2:$A$53,0))="Hoàn thành",INDEX(BE_Tasks!$Z$2:$Z$53,MATCH("BE-B06",BE_Tasks!$A$2:$A$53,0))="")),"Đủ điều kiện","Chờ phụ thuộc") -> Chờ phụ thuộc | Z25: =IF(AND(P25="Hoàn thành",OR(X25<1,Y25<>"Đủ điều kiện",AND(AE25="",AD25=""))),"Thiếu bước / phụ thuộc / bằng chứng","") | AG25: Mở task
A26: BE-B08 | B26: P3 | C26: 8 | D26: B | E26: C | F26: Đề nghị lịch xem và xét duyệt | G26: 5 | H26: 4 | I26: API-091, API-092, API-093, API-094 | J26: backend/src/modules/viewings/** backend/tests/viewings/** backend/tests/e2e/viewing-contract/** backend/contracts/viewings.* database/source/house-rights.sql database/source/post-review-quota.sql database/source/viewing-proposals.sql backend/tests/sql-property/** | K26: BE-A08, BE-B07 | N26: Idempotency UUID; một PENDING/tenant+room; proposal chưa giữ giờ/chỗ. Accept khóa room, recheck context/quyền/tài khoản và overlap; tạo đúng một schedule cùng transaction. Withdraw/expire theo now, không đợi worker; kết quả gửi vào notification source. | O26: Hai proposal trùng giờ có thể chờ nhưng chỉ một schedule nếu xung đột. Duyệt lại trả linked schedule, không tạo lần hai. | P26: Chưa làm | Q26: Chưa | R26: Chưa | S26: Chưa | T26: Chưa | U26: Chưa | V26: Chưa | W26: Chưa | X26: =COUNTIF(Q26:W26,"Xong")/7 -> 0 | Y26: =IF(AND(AND(INDEX(BE_Tasks!$P$2:$P$53,MATCH("BE-A08",BE_Tasks!$A$2:$A$53,0))="Hoàn thành",INDEX(BE_Tasks!$Z$2:$Z$53,MATCH("BE-A08",BE_Tasks!$A$2:$A$53,0))=""),AND(INDEX(BE_Tasks!$P$2:$P$53,MATCH("BE-B07",BE_Tasks!$A$2:$A$53,0))="Hoàn thành",INDEX(BE_Tasks!$Z$2:$Z$53,MATCH("BE-B07",BE_Tasks!$A$2:$A$53,0))="")),"Đủ điều kiện","Chờ phụ thuộc") -> Chờ phụ thuộc | Z26: =IF(AND(P26="Hoàn thành",OR(X26<1,Y26<>"Đủ điều kiện",AND(AE26="",AD26=""))),"Thiếu bước / phụ thuộc / bằng chứng","") | AG26: Mở task
A27: BE-B09 | B27: P3 | C27: 9 | D27: B | E27: C | F27: Tạo lịch trực tiếp, tham dự và ý định thuê | G27: 5 | H27: 6 | I27: API-095, API-096, API-097, API-098, API-099, API-100 | J27: backend/src/modules/viewings/** backend/tests/viewings/** backend/tests/e2e/viewing-contract/** backend/contracts/viewings.* database/source/house-rights.sql database/source/post-review-quota.sql database/source/viewing-proposals.sql backend/tests/sql-property/** | K27: BE-B08 | N27: Hẹn trực tiếp cần tin thuê đúng conversation/room; UTC và duration 30/60/90/120. ATTENDED/NO_SHOW/CANCEL đúng vai trò/thời điểm; quyết định thuê theo chuyển trạng thái cho phép. Công bố fixture viewing đủ điều kiện và không đủ điều kiện; C không viết một lịch riêng. | O27: Khoảng [start,end) không chồng nhau, liền kề được; không hẹn bằng ROOMMATE. AGREED không giữ phòng; withdrawal bị chặn khi còn hợp đồng mở. | P27: Chưa làm | Q27: Chưa | R27: Chưa | S27: Chưa | T27: Chưa | U27: Chưa | V27: Chưa | W27: Chưa | X27: =COUNTIF(Q27:W27,"Xong")/7 -> 0 | Y27: =IF(AND(AND(INDEX(BE_Tasks!$P$2:$P$53,MATCH("BE-B08",BE_Tasks!$A$2:$A$53,0))="Hoàn thành",INDEX(BE_Tasks!$Z$2:$Z$53,MATCH("BE-B08",BE_Tasks!$A$2:$A$53,0))="")),"Đủ điều kiện","Chờ phụ thuộc") -> Chờ phụ thuộc | Z27: =IF(AND(P27="Hoàn thành",OR(X27<1,Y27<>"Đủ điều kiện",AND(AE27="",AD27=""))),"Thiếu bước / phụ thuộc / bằng chứng","") | AG27: Mở task
A28: BE-B10 | B28: P3 | C28: 10 | D28: B | E28: C | F28: Bàn giao và kiểm tra lịch khi hợp đồng giữ phòng | G28: 3 | H28: 0 | J28: backend/src/modules/viewings/** backend/tests/viewings/** backend/tests/e2e/viewing-contract/** backend/contracts/viewings.* | K28: BE-B09, BE-C05 | N28: Gửi contract từ lịch bàn giao, kiểm tra lịch/proposal ở mọi post cùng room. Phân biệt lịch chưa bắt đầu với đang diễn ra/đã hết; trả event tổng hợp cho A. Hủy contract không khôi phục lịch cũ; lập bug đúng owner file/SQL thay vì sửa chéo. | O28: QA03/04 chạy với cả endpoint lịch và contract thật. Timeline A11 và list lịch đều đọc cùng trạng thái. | P28: Chưa làm | Q28: Chưa | R28: Chưa | S28: Chưa | T28: Chưa | U28: Chưa | V28: Chưa | W28: Chưa | X28: =COUNTIF(Q28:W28,"Xong")/7 -> 0 | Y28: =IF(AND(AND(INDEX(BE_Tasks!$P$2:$P$53,MATCH("BE-B09",BE_Tasks!$A$2:$A$53,0))="Hoàn thành",INDEX(BE_Tasks!$Z$2:$Z$53,MATCH("BE-B09",BE_Tasks!$A$2:$A$53,0))=""),AND(INDEX(BE_Tasks!$P$2:$P$53,MATCH("BE-C05",BE_Tasks!$A$2:$A$53,0))="Hoàn thành",INDEX(BE_Tasks!$Z$2:$Z$53,MATCH("BE-C05",BE_Tasks!$A$2:$A$53,0))="")),"Đủ điều kiện","Chờ phụ thuộc") -> Chờ phụ thuộc | Z28: =IF(AND(P28="Hoàn thành",OR(X28<1,Y28<>"Đủ điều kiện",AND(AE28="",AD28=""))),"Thiếu bước / phụ thuộc / bằng chứng","") | AG28: Mở task
A29: BE-B11 | B29: P4 | C29: 11 | D29: B | E29: C | F29: Hồ sơ ở ghép và tình trạng nhà ở | G29: 5 | H29: 5 | I29: API-062, API-063, API-064, API-066, API-067 | J29: backend/src/modules/roommates/** backend/tests/roommates/** backend/contracts/roommates.* | K29: BE-B04, BE-C02 | N29: PUT profile version, budget/location/available date; IN_SYSTEM do server suy từ đúng member ACTIVE. EXTERNAL tối đa 1.000 ký tự và bỏ mô tả khi đổi trạng thái. Giá trị lifestyle giữ schema JSON theo criterion, không thêm cột mỗi thói quen. | O29: Không tự gắn memberId client gửi; stale version 409. Người chưa có ACTIVE được tự khai chưa có chỗ/ngoài hệ thống đúng rule. | P29: Chưa làm | Q29: Chưa | R29: Chưa | S29: Chưa | T29: Chưa | U29: Chưa | V29: Chưa | W29: Chưa | X29: =COUNTIF(Q29:W29,"Xong")/7 -> 0 | Y29: =IF(AND(AND(INDEX(BE_Tasks!$P$2:$P$53,MATCH("BE-B04",BE_Tasks!$A$2:$A$53,0))="Hoàn thành",INDEX(BE_Tasks!$Z$2:$Z$53,MATCH("BE-B04",BE_Tasks!$A$2:$A$53,0))=""),AND(INDEX(BE_Tasks!$P$2:$P$53,MATCH("BE-C02",BE_Tasks!$A$2:$A$53,0))="Hoàn thành",INDEX(BE_Tasks!$Z$2:$Z$53,MATCH("BE-C02",BE_Tasks!$A$2:$A$53,0))="")),"Đủ điều kiện","Chờ phụ thuộc") -> Chờ phụ thuộc | Z29: =IF(AND(P29="Hoàn thành",OR(X29<1,Y29<>"Đủ điều kiện",AND(AE29="",AD29=""))),"Thiếu bước / phụ thuộc / bằng chứng","") | AG29: Mở task
A30: BE-B12 | B30: P4 | C30: 12 | D30: B | E30: C | F30: Danh mục tiêu chí ghép linh động | G30: 3 | H30: 3 | I30: API-065, API-069, API-070 | J30: backend/src/modules/roommates/** backend/tests/roommates/** backend/contracts/roommates.* | K30: BE-B11 | M30: D02 | N30: Code duy nhất, valueType/allowedValues hợp lệ; mandatory cần preferredValue, importance 0–5. Không đổi kiểu khiến profile cũ mất nghĩa; thay đổi tương thích cần version/plan. Đề xuất D02 cho người chốt; giải thích score v1 và xử lý thiếu dữ liệu. | O30: Self/preferred JSON sai kiểu hoặc category ngoài tập bị chặn. Ngừng tiêu chí vẫn giữ giá trị lịch sử theo chính sách. | P30: Chưa làm | Q30: Chưa | R30: Chưa | S30: Chưa | T30: Chưa | U30: Chưa | V30: Chưa | W30: Chưa | X30: =COUNTIF(Q30:W30,"Xong")/7 -> 0 | Y30: =IF(AND(AND(INDEX(BE_Tasks!$P$2:$P$53,MATCH("BE-B11",BE_Tasks!$A$2:$A$53,0))="Hoàn thành",INDEX(BE_Tasks!$Z$2:$Z$53,MATCH("BE-B11",BE_Tasks!$A$2:$A$53,0))="")),"Đủ điều kiện","Chờ phụ thuộc") -> Chờ phụ thuộc | Z30: =IF(AND(P30="Hoàn thành",OR(X30<1,Y30<>"Đủ điều kiện",AND(AE30="",AD30=""))),"Thiếu bước / phụ thuộc / bằng chứng","") | AG30: Mở task
A31: BE-B13 | B31: P4 | C31: 13 | D31: B | E31: C | F31: Mời kết nối và tạo chat đúng một lần | G31: 5 | H31: 5 | I31: API-071, API-072, API-073, API-074, API-075 | J31: backend/src/modules/roommates/** backend/tests/roommates/** backend/contracts/roommates.* | K31: BE-B12, BE-A08 | M31: D03 | N31: Người gửi có profile, cặp chuẩn hóa chống hai chiều, receiver mới được phản hồi. ACCEPT ghi request và ensureRoommateConversation(tx) nguyên tử, không tạo join/hold. End ghi ended_at/reason, chặn gửi mới; policy đọc lịch sử D03 phải chốt cùng A. | O31: Gửi chéo không tự accept; retry accept không sinh chat trùng. Hồ sơ cũ vẫn phản hồi được; room capacity không chặn kết nối đơn thuần. | P31: Chưa làm | Q31: Chưa | R31: Chưa | S31: Chưa | T31: Chưa | U31: Chưa | V31: Chưa | W31: Chưa | X31: =COUNTIF(Q31:W31,"Xong")/7 -> 0 | Y31: =IF(AND(AND(INDEX(BE_Tasks!$P$2:$P$53,MATCH("BE-B12",BE_Tasks!$A$2:$A$53,0))="Hoàn thành",INDEX(BE_Tasks!$Z$2:$Z$53,MATCH("BE-B12",BE_Tasks!$A$2:$A$53,0))=""),AND(INDEX(BE_Tasks!$P$2:$P$53,MATCH("BE-A08",BE_Tasks!$A$2:$A$53,0))="Hoàn thành",INDEX(BE_Tasks!$Z$2:$Z$53,MATCH("BE-A08",BE_Tasks!$A$2:$A$53,0))="")),"Đủ điều kiện","Chờ phụ thuộc") -> Chờ phụ thuộc | Z31: =IF(AND(P31="Hoàn thành",OR(X31<1,Y31<>"Đủ điều kiện",AND(AE31="",AD31=""))),"Thiếu bước / phụ thuộc / bằng chứng","") | AG31: Mở task
A32: BE-B14 | B32: P5 | C32: 14 | D32: B | E32: C | F32: Báo cáo vi phạm và kết luận | G32: 5 | H32: 5 | I32: API-156, API-157, API-158, API-159, API-160 | J32: backend/src/modules/reviews/** backend/src/modules/reports/** backend/tests/content-moderation/** | K32: BE-B07, BE-A05, BE-A04 | N32: Target đúng một loại và người báo cáo có quyền đọc; file bằng chứng PRIVATE thuộc actor. Hàng đợi/details/decision với actor/time/resolution; audit không tự khóa user hoặc hủy thuê. Giữ các FK và che kết quả điều tra riêng tư khỏi reporter khi không được phép. | O32: Không nhắm nhiều target cùng report; bản đóng không bị form cũ mở lại. Nếu cần khóa account, gọi cổng A theo nghiệp vụ; không viết users repository mới. | P32: Chưa làm | Q32: Chưa | R32: Chưa | S32: Chưa | T32: Chưa | U32: Chưa | V32: Chưa | W32: Chưa | X32: =COUNTIF(Q32:W32,"Xong")/7 -> 0 | Y32: =IF(AND(AND(INDEX(BE_Tasks!$P$2:$P$53,MATCH("BE-B07",BE_Tasks!$A$2:$A$53,0))="Hoàn thành",INDEX(BE_Tasks!$Z$2:$Z$53,MATCH("BE-B07",BE_Tasks!$A$2:$A$53,0))=""),AND(INDEX(BE_Tasks!$P$2:$P$53,MATCH("BE-A05",BE_Tasks!$A$2:$A$53,0))="Hoàn thành",INDEX(BE_Tasks!$Z$2:$Z$53,MATCH("BE-A05",BE_Tasks!$A$2:$A$53,0))=""),AND(INDEX(BE_Tasks!$P$2:$P$53,MATCH("BE-A04",BE_Tasks!$A$2:$A$53,0))="Hoàn thành",INDEX(BE_Tasks!$Z$2:$Z$53,MATCH("BE-A04",BE_Tasks!$A$2:$A$53,0))="")),"Đủ điều kiện","Chờ phụ thuộc") -> Chờ phụ thuộc | Z32: =IF(AND(P32="Hoàn thành",OR(X32<1,Y32<>"Đủ điều kiện",AND(AE32="",AD32=""))),"Thiếu bước / phụ thuộc / bằng chứng","") | AG32: Mở task
A33: BE-B15 | B33: P6 | C33: 15 | D33: B | E33: C | F33: Danh sách người phù hợp theo chính sách đã chốt | G33: 5 | H33: 1 | I33: API-068 | J33: backend/src/modules/roommates/** backend/tests/roommates/** backend/contracts/roommates.* | K33: BE-B13 | M33: D02 | N33: Lọc self/inactive, location/budget và tiêu chí bắt buộc. AlgorithmVersion/score/explanations cố định theo D02, test cùng dữ liệu thiếu/ngân sách biên. Nếu D02 chưa chốt, ghi Bị chặn cho task; không trả score mẫu như kết quả thật. | O33: Cùng input+algorithmVersion có kết quả xác định, không lộ PII cư dân. Cấu trúc output giữ contract, có pagination/sort ổn định. | P33: Chưa làm | Q33: Chưa | R33: Chưa | S33: Chưa | T33: Chưa | U33: Chưa | V33: Chưa | W33: Chưa | X33: =COUNTIF(Q33:W33,"Xong")/7 -> 0 | Y33: =IF(AND(AND(INDEX(BE_Tasks!$P$2:$P$53,MATCH("BE-B13",BE_Tasks!$A$2:$A$53,0))="Hoàn thành",INDEX(BE_Tasks!$Z$2:$Z$53,MATCH("BE-B13",BE_Tasks!$A$2:$A$53,0))="")),"Đủ điều kiện","Chờ phụ thuộc") -> Chờ phụ thuộc | Z33: =IF(AND(P33="Hoàn thành",OR(X33<1,Y33<>"Đủ điều kiện",AND(AE33="",AD33=""))),"Thiếu bước / phụ thuộc / bằng chứng","") | AG33: Mở task
A34: BE-B16 | B34: P6 | C34: 16 | D34: B | E34: C | F34: Đánh giá theo bằng chứng cư trú và audit | G34: 5 | H34: 3 | I34: API-153, API-154, API-155 | J34: backend/src/modules/reviews/** backend/src/modules/reports/** backend/tests/content-moderation/** | K34: BE-B14, BE-C02, BE-A15 | M34: D13, D14 | N34: Unique reviewer+room+contract; đúng roomTenant evidence của actor, rating 1–5. Public chỉ PUBLISHED, moderation không sửa bằng chứng hợp đồng/cư trú. Giữ trạng thái cần chốt nếu D13/D14 chưa có quyết định, không ghi nhầm target_post_id. | O34: Tài khoản chỉ từng xem phòng không được review; không đánh giá trùng. Ẩn review giữ audit đúng đối tượng và không làm mất cư trú. | P34: Chưa làm | Q34: Chưa | R34: Chưa | S34: Chưa | T34: Chưa | U34: Chưa | V34: Chưa | W34: Chưa | X34: =COUNTIF(Q34:W34,"Xong")/7 -> 0 | Y34: =IF(AND(AND(INDEX(BE_Tasks!$P$2:$P$53,MATCH("BE-B14",BE_Tasks!$A$2:$A$53,0))="Hoàn thành",INDEX(BE_Tasks!$Z$2:$Z$53,MATCH("BE-B14",BE_Tasks!$A$2:$A$53,0))=""),AND(INDEX(BE_Tasks!$P$2:$P$53,MATCH("BE-C02",BE_Tasks!$A$2:$A$53,0))="Hoàn thành",INDEX(BE_Tasks!$Z$2:$Z$53,MATCH("BE-C02",BE_Tasks!$A$2:$A$53,0))=""),AND(INDEX(BE_Tasks!$P$2:$P$53,MATCH("BE-A15",BE_Tasks!$A$2:$A$53,0))="Hoàn thành",INDEX(BE_Tasks!$Z$2:$Z$53,MATCH("BE-A15",BE_Tasks!$A$2:$A$53,0))="")),"Đủ điều kiện","Chờ phụ thuộc") -> Chờ phụ thuộc | Z34: =IF(AND(P34="Hoàn thành",OR(X34<1,Y34<>"Đủ điều kiện",AND(AE34="",AD34=""))),"Thiếu bước / phụ thuộc / bằng chứng","") | AG34: Mở task
A35: BE-B17 | B35: P6 | C35: 17 | D35: B | E35: C | F35: Dashboard chủ trọ bằng metric ports | G35: 3 | H35: 1 | I35: API-175 | J35: backend/src/modules/properties/** backend/src/modules/house-rights/** backend/tests/properties/** backend/tests/fixtures/B/** backend/tests/contracts/B/** backend/tests/e2e/property-*/** backend/contracts/properties.* | K35: BE-B16, BE-A13, BE-C12 | N35: Scope landlord cho từng metric; ACTIVE tính occupied, không đồng nhất reserved với occupied. Lịch chưa hết giờ, hóa đơn UNPAID/OVERDUE và pending requests có nguồn đúng module. Có asOf, tách truy vấn count khỏi trả danh tính cư dân. | O35: Không cộng nhầm dữ liệu chủ khác; amount decimal và status phù hợp. Contract tests của metric ports phát hiện consumer dùng field cũ. | P35: Chưa làm | Q35: Chưa | R35: Chưa | S35: Chưa | T35: Chưa | U35: Chưa | V35: Chưa | W35: Chưa | X35: =COUNTIF(Q35:W35,"Xong")/7 -> 0 | Y35: =IF(AND(AND(INDEX(BE_Tasks!$P$2:$P$53,MATCH("BE-B16",BE_Tasks!$A$2:$A$53,0))="Hoàn thành",INDEX(BE_Tasks!$Z$2:$Z$53,MATCH("BE-B16",BE_Tasks!$A$2:$A$53,0))=""),AND(INDEX(BE_Tasks!$P$2:$P$53,MATCH("BE-A13",BE_Tasks!$A$2:$A$53,0))="Hoàn thành",INDEX(BE_Tasks!$Z$2:$Z$53,MATCH("BE-A13",BE_Tasks!$A$2:$A$53,0))=""),AND(INDEX(BE_Tasks!$P$2:$P$53,MATCH("BE-C12",BE_Tasks!$A$2:$A$53,0))="Hoàn thành",INDEX(BE_Tasks!$Z$2:$Z$53,MATCH("BE-C12",BE_Tasks!$A$2:$A$53,0))="")),"Đủ điều kiện","Chờ phụ thuộc") -> Chờ phụ thuộc | Z35: =IF(AND(P35="Hoàn thành",OR(X35<1,Y35<>"Đủ điều kiện",AND(AE35="",AD35=""))),"Thiếu bước / phụ thuộc / bằng chứng","") | AG35: Mở task
A36: BE-B18 | B36: P6 | C36: 18 | D36: B | E36: C | F36: Worker hết quyền nhà và bảo toàn dữ liệu cũ | G36: 2 | H36: 0 | J36: backend/src/modules/properties/** backend/src/modules/house-rights/** backend/tests/properties/** backend/tests/fixtures/B/** backend/tests/contracts/B/** backend/tests/e2e/property-*/** backend/contracts/properties.* database/source/house-rights.sql database/source/post-review-quota.sql database/source/viewing-proposals.sql backend/tests/sql-property/** | K36: BE-B05 | N36: APPROVED valid_until<todayVN → EXPIRED theo chính sách, giữ proof/history. Không xóa/ẩn vật lý từng post hoặc kết thúc contract để giả mất quyền. Đăng ký worker qua manifest riêng, không sửa worker registry chung. | O36: Job chậm vẫn không công khai tin hết quyền; chạy lặp an toàn. Luồng rời/kết thúc hợp đồng cũ tiếp tục dùng được. | P36: Chưa làm | Q36: Chưa | R36: Chưa | S36: Chưa | T36: Chưa | U36: Chưa | V36: Chưa | W36: Chưa | X36: =COUNTIF(Q36:W36,"Xong")/7 -> 0 | Y36: =IF(AND(AND(INDEX(BE_Tasks!$P$2:$P$53,MATCH("BE-B05",BE_Tasks!$A$2:$A$53,0))="Hoàn thành",INDEX(BE_Tasks!$Z$2:$Z$53,MATCH("BE-B05",BE_Tasks!$A$2:$A$53,0))="")),"Đủ điều kiện","Chờ phụ thuộc") -> Chờ phụ thuộc | Z36: =IF(AND(P36="Hoàn thành",OR(X36<1,Y36<>"Đủ điều kiện",AND(AE36="",AD36=""))),"Thiếu bước / phụ thuộc / bằng chứng","") | AG36: Mở task
A37: BE-B19 | B37: P7 | C37: 19 | D37: B | E37: C | F37: Kiểm thử module nhà/tin/lịch và nội dung | G37: 5 | H37: 0 | J37: backend/src/modules/properties/** backend/src/modules/house-rights/** backend/tests/properties/** backend/tests/fixtures/B/** backend/tests/contracts/B/** backend/tests/e2e/property-*/** backend/contracts/properties.* backend/src/modules/posts/** backend/tests/posts/** backend/contracts/posts.* backend/src/modules/viewings/** backend/tests/viewings/** backend/tests/e2e/viewing-contract/** backend/contracts/viewings.* backend/src/modules/roommates/** backend/tests/roommates/** backend/contracts/roommates.* backend/src/modules/reviews/** backend/src/modules/reports/** backend/tests/content-moderation/** | K37: BE-B10, BE-B15, BE-B16, BE-B17, BE-B18 | N37: QA01/02/04/09/13/14/15 có test concurrency và quyền chéo tài khoản. Kiểm tra D07 upload+post rollback; search/favorites/shared card sau mất quyền. Nộp report test, collection requests và danh sách source SQL đã thay cho A. | O37: Mỗi endpoint B có DTO/auth/logic/test/docs/review và phạm vi file đúng owner. Không sửa generated SQL/seed/tests của C để làm CI xanh. | P37: Chưa làm | Q37: Chưa | R37: Chưa | S37: Chưa | T37: Chưa | U37: Chưa | V37: Chưa | W37: Chưa | X37: =COUNTIF(Q37:W37,"Xong")/7 -> 0 | Y37: =IF(AND(AND(INDEX(BE_Tasks!$P$2:$P$53,MATCH("BE-B10",BE_Tasks!$A$2:$A$53,0))="Hoàn thành",INDEX(BE_Tasks!$Z$2:$Z$53,MATCH("BE-B10",BE_Tasks!$A$2:$A$53,0))=""),AND(INDEX(BE_Tasks!$P$2:$P$53,MATCH("BE-B15",BE_Tasks!$A$2:$A$53,0))="Hoàn thành",INDEX(BE_Tasks!$Z$2:$Z$53,MATCH("BE-B15",BE_Tasks!$A$2:$A$53,0))=""),AND(INDEX(BE_Tasks!$P$2:$P$53,MATCH("BE-B16",BE_Tasks!$A$2:$A$53,0))="Hoàn thành",INDEX(BE_Tasks!$Z$2:$Z$53,MATCH("BE-B16",BE_Tasks!$A$2:$A$53,0))=""),AND(INDEX(BE_Tasks!$P$2:$P$53,MATCH("BE-B17",BE_Tasks!$A$2:$A$53,0))="Hoàn thành",INDEX(BE_Tasks!$Z$2:$Z$53,MATCH("BE-B17",BE_Tasks!$A$2:$A$53,0))=""),AND(INDEX(BE_Tasks!$P$2:$P$53,MATCH("BE-B18",BE_Tasks!$A$2:$A$53,0))="Hoàn thành",INDEX(BE_Tasks!$Z$2:$Z$53,MATCH("BE-B18",BE_Tasks!$A$2:$A$53,0))="")),"Đủ điều kiện","Chờ phụ thuộc") -> Chờ phụ thuộc | Z37: =IF(AND(P37="Hoàn thành",OR(X37<1,Y37<>"Đủ điều kiện",AND(AE37="",AD37=""))),"Thiếu bước / phụ thuộc / bằng chứng","") | AG37: Mở task
A38: BE-C01 | B38: P0 | C38: 1 | D38: C | E38: A | F38: Chốt trạng thái thuê, transaction và cổng cư trú | G38: 5 | H38: 0 | J38: backend/src/modules/rentals/** backend/tests/rentals/** backend/tests/fixtures/C/** backend/tests/contracts/C/** backend/tests/e2e/rental-*/** backend/contracts/rentals.* database/source/workflows.sql database/source/contract-viewing-cleanup.sql backend/tests/sql-rental/** | M38: D06, D10, D11 | N38: Vẽ chuyển trạng thái và lock order roomId tăng dần; xác định procedure tự commit. Công bố ResidencyReadPort/contract snapshot và fixture của C; A/B không join/ghi trực tiếp các bảng này trong service của họ. D10 expectedRevision và D11 import được ghi là mở rộng cần làm; không xác nhận nhầm phiên bản. | O38: A02/B01 cùng duyệt contract; chưa chọn framework vẫn chuẩn bị SQL/fixture được. Planned/active/left/cancelled, payer cũ, đại diện ban đầu/hiện tại được phân biệt. | P38: Chưa làm | Q38: Chưa | R38: Chưa | S38: Chưa | T38: Chưa | U38: Chưa | V38: Chưa | W38: Chưa | X38: =COUNTIF(Q38:W38,"Xong")/7 -> 0 | Y38: =IF(TRUE,"Đủ điều kiện","Chờ phụ thuộc") -> Đủ điều kiện | Z38: =IF(AND(P38="Hoàn thành",OR(X38<1,Y38<>"Đủ điều kiện",AND(AE38="",AD38=""))),"Thiếu bước / phụ thuộc / bằng chứng","") | AG38: Mở task
